Workbook
Name listTop: '【103399】クラレ（三ツワフロンテック） 原価一覧'!$E$9
Name TEL: [2]リスト!$C$1:$C$26
Name TEL: [2]リスト!$C$1:$C$26
Name TEL: [2]リスト!$C$1:$C$26
Name TEL: [2]リスト!$C$1:$C$26
Name TEL: '12.10.17 【追加】購入依頼書-5'!$C$1:$C$26
Name TEL: [3]リスト!$C$1:$C$26
Name TEL: [3]リスト!$C$1:$C$26
Name TEL: [3]リスト!$C$1:$C$26
Name TEL: [3]リスト!$C$1:$C$26
Name TEL: '12.11.06 【追加】購入依頼書-5'!$C$1:$C$26
Name TEL: [4]リスト!$C$1:$C$26
Name TEL: [4]リスト!$C$1:$C$26
Name TEL: [4]リスト!$C$1:$C$26
Name TEL: [4]リスト!$C$1:$C$26
Name TEL: '購入依頼書-5'!$C$1:$C$26
Name TEL: '12.10.04 【追加】購入依頼書-5'!$C$1:$C$26
Name あ: #REF!
Name あ: #REF!
Name あ: #REF!
Name あ: #REF!
Name あ: #REF!
Name あ: #REF!
Name あ: #REF!
Name あ: #REF!
Name あ: #REF!
Name あ: #REF!
Name あ: #REF!
Name あ: #REF!
Name あ: #REF!
Name あ: #REF!
Name あ: #REF!
Name あ: #REF!
Name 会社: #REF!
Name 会社: #REF!
Name 会社: #REF!
Name 会社: #REF!
Name 会社: #REF!
Name 会社: #REF!
Name 会社: #REF!
Name 会社: #REF!
Name 会社: #REF!
Name 会社: #REF!
Name 会社: #REF!
Name 会社: #REF!
Name 会社: #REF!
Name 会社: #REF!
Name 会社: #REF!
Name 会社: #REF!
Name 会社名: [2]リスト!$A$1:$A$26
Name 会社名: [2]リスト!$A$1:$A$26
Name 会社名: [2]リスト!$A$1:$A$26
Name 会社名: [2]リスト!$A$1:$A$26
Name 会社名: '12.10.17 【追加】購入依頼書-5'!$A$1:$A$26
Name 会社名: [3]リスト!$A$1:$A$26
Name 会社名: [3]リスト!$A$1:$A$26
Name 会社名: [3]リスト!$A$1:$A$26
Name 会社名: [3]リスト!$A$1:$A$26
Name 会社名: '12.11.06 【追加】購入依頼書-5'!$A$1:$A$26
Name 会社名: [4]リスト!$A$1:$A$26

Sheet 【94485】 NDK 原価一覧1-27出荷
B2: お客先名 | E2: NDK | G2: 合計金額 | J2: =SUM(H:H) -> 5382920
B3: 担当営業 | E3: 青木
B4: 受注番号 | E4: 94485
B5: 希望納期 | E5: 40922
B6: 最終納品
B8: 見積り分類 | C8: メーカー | D8: 仕入先 | E8: 品名 / 型式 | F8: 数量 | G8: 単価 | H8: 金額 | I8: 分類合計 | J8: 詳細 | K8: 備考 | L8: 技術分類 | M8: 発注日 | N8: 発注 | O8: 納期 | P8: 入荷予定日 | Q8: 入荷日
B9: 1 | C9: Asymtek | D9: Asymtek | E9: ZDA-1420510 | F9: 2 | H9: =F9*G9 -> 0
B10: 2 | C10: Asymtek | D10: Asymtek | E10: ZDA-2710370 | F10: 2 | H10: =F10*G10 -> 0
B11: 3 | C11: Asymtek | D11: Asymtek | E11: ZDA-2410321 | F11: 2 | H11: =F11*G11 -> 0
B12: 4 | C12: Asymtek | D12: Asymtek | E12: MT-30005-P67 | F12: 2 | H12: =F12*G12 -> 0
B13: 5 | C13: 蛇の目 | D13: 蛇の目 | E13: JR2203NH | F13: 2 | G13: 400000 | H13: =F13*G13 -> 800000 | K13: 14218 | M13: 40879 | N13: ○ | Q13: 12/19 蛇⇒ｵｼﾞｯｸ
B14: 5 | C14: 蛇の目 | D14: 蛇の目 | E14: 荷造り運賃 | F14: 2 | G14: 10000 | H14: =F14*G14 -> 20000 | K14: 14218 | M14: 40879 | N14: ○ | Q14: 12/19 蛇⇒ｵｼﾞｯｸ
B15: 6 | C15: 蛇の目 | D15: 蛇の目 | E15: COM増設 | F15: 2 | G15: 20000 | H15: =F15*G15 -> 40000 | K15: 14218 | M15: 40879 | N15: ○ | Q15: 12/19 蛇⇒ｵｼﾞｯｸ
B16: 7 | C16: 蛇の目 | D16: 蛇の目 | E16: JR-TB | F16: 2 | G16: 38000 | H16: =F16*G16 -> 76000 | K16: 在庫分使用 | M16: 40879 | N16: ×
B17: 8 | C17: パナソニック | D17: 蛇の目 | E17: A110 | F17: 2 | G17: 155400 | H17: =F17*G17 -> 310800 | J17: ANMA110 | K17: 14217 | L17: Z | M17: 40879 | N17: ○ | Q17: 12/16 蛇⇒ｵｼﾞｯｸ
B18: 8 | C18: パナソニック | D18: 蛇の目 | E18: RS232C | F18: 2 | G18: 12000 | H18: =F18*G18 -> 24000 | J18: 960536106 | K18: 14217 | L18: Z | M18: 40879 | N18: ○ | Q18: 12/16 蛇⇒ｵｼﾞｯｸ
B19: 8 | C19: パナソニック | D19: 蛇の目 | E19: 送料 | F19: 2 | G19: 1000 | H19: =F19*G19 -> 2000 | J19: - | K19: 14217 | L19: Z | M19: 40879 | N19: ○ | Q19: 12/16 蛇⇒ｵｼﾞｯｸ
B20: 9 | C20: パナソニック | D20: 蛇の目 | E20: CSマウントカメラ | F20: 2 | G20: 54600 | H20: =F20*G20 -> 109200 | J20: ANM832 | K20: 14217 | L20: Z | M20: 40879 | N20: ○ | Q20: 12/16 蛇⇒ｵｼﾞｯｸ
B21: 10 | C21: パナソニック | D21: 蛇の目 | E21: 操作キーパット | F21: 2 | G21: 7900 | H21: =F21*G21 -> 15800 | J21: ANM85202 | K21: 14217 | L21: Z | M21: 40879 | N21: ○ | Q21: 12/16 蛇⇒ｵｼﾞｯｸ
B22: 11 | C22: パナソニック | D22: 松下制御テクノ | E22: レンズ | F22: 2 | G22: 23000 | H22: =F22*G22 -> 46000 | J22: ANB846NL | K22: 14216 | L22: Z | M22: 40879 | N22: ○ | P22: 40893 | Q22: 40893
B23: 12 | C23: オプトアート | D23: 都機工 | E23: リアコンバーターレンズ | F23: 2 | G23: 10800 | H23: =F23*G23 -> 21600 | J23: TVR02 | K23: 14215 | L23: Z | M23: 40879 | N23: ○ | Q23: 12/..8
B24: 12 | C24: オプトアート | D24: 都機工 | E24: 送料 | F24: 2 | G24: 1000 | H24: =F24*G24 -> 2000 | J24: - | K24: 14215 | L24: Z | M24: 40879 | N24: ○ | Q24: 12/..8
B25: 12 | C25: VSテクノロジー | D25: VSテクノロジー | E25: 中間リング | F25: 4 | G25: 1380 | H25: =F25*G25 -> 5520 | J25: VS-EXR10 | K25: 14215 | L25: Z | M25: 40879 | N25: ○ | P25: 40904 | Q25: 40904
B26: 13 | C26: CCS | D26: CCS | E26: LED安定照明器 | F26: 2 | G26: 44000 | H26: =F26*G26 -> 88000 | J26: LDR2-32RD | K26: 14213 | L26: Z | M26: 40879 | N26: ○ | P26: 40904 | Q26: 40904
B27: 13 | C27: CCS | D27: CCS | E27: コントローラー | F27: 2 | G27: 13600 | H27: =F27*G27 -> 27200 | J27: PSB-512VL | K27: 14213 | L27: Z | M27: 40879 | N27: ○ | P27: 40904 | Q27: 40904
B28: 13 | C28: CCS | D28: CCS | E28: ケーブル | F28: 2 | G28: 2400 | H28: =F28*G28 -> 4800 | J28: CB-2 | K28: 14213 | L28: Z | M28: 40879 | N28: ○ | P28: 40904 | Q28: 40904
B29: 14 | C29: オジックとダイア | D29: オジックとダイア | E29: 搬送及び制御機構 | F29: 2 | G29: 1895000 | H29: =F29*G29 -> 3790000 | J29: 搬送装置 | K29: 14264 | M29: 40886 | N29: ○ | P29: 40924
B30: 15 | E30: 調整費 | F30: 2 | H30: =F30*G30 -> 0
B31: 16 | E31: 諸経費 | F31: 2 | H31: =F31*G31 -> 0
B32: 17 | E32: 特別値引き

Sheet 【94652】 ビステオン 原価一覧1-31出荷
B2: お客先名 | E2: ﾋﾞｽﾃｵﾝ | G2: 合計金額 | J2: =SUM(H:H) -> 923064
B3: 担当営業 | E3: 本郷
B4: 受注番号 | E4: 94652
B5: 希望納期 | E5: 40927
B6: 最終納品 | E6: 40940
B8: 見積り分類 | C8: メーカー | D8: 仕入先 | E8: 品名 / 型式 | F8: 数量 | G8: 単価 | H8: 金額 | I8: 分類合計 | J8: 詳細 | K8: 備考 | L8: 技術分類 | M8: 発注日 | N8: 発注 | O8: 納期 | P8: 入荷予定日 | Q8: 入荷日
B9: 34 | C9: 遠藤製作所 | D9: 遠藤製作所 | E9: 94652-Y01 | F9: 1 | G9: 6800 | H9: =F9*G9 -> 6800 | J9: ツール取付板 | L9: Y | M9: 40914 | Q9: 40926
B10: 34 | C10: 遠藤製作所 | D10: 遠藤製作所 | E10: SS40077 | F10: 1 | G10: 13800 | H10: =F10*G10 -> 13800 | J10: 725D,725DA用ホルダ（P=25） | L10: Y | M10: 40914 | Q10: 40926
B11: 35 | C11: 遠藤製作所 | D11: 遠藤製作所 | E11: SS3244 | F11: 1 | G11: 7800 | H11: =F11*G11 -> 7800 | J11: タブテーブル（L110) | L11: Y | M11: 40914 | Q11: 40926
B12: 35 | C12: 遠藤製作所 | D12: 遠藤製作所 | E12: SS40564 | F12: 1 | G12: 19500 | H12: =F12*G12 -> 19500 | J12: 新カートリッジホルダ（タブ用） | L12: Y | M12: 40914 | Q12: 40926
B13: 35 | C13: 遠藤製作所 | D13: 遠藤製作所 | E13: 94652-Z01 | F13: 1 | G13: 10500 | H13: =F13*G13 -> 10500 | J13: レギュレータ取付板 | L13: Z | M13: 40914 | Q13: 40926
B14: 3 | C14: 遠藤製作所 | D14: 遠藤製作所 | E14: SS4672 | F14: 1 | G14: 13000 | H14: =F14*G14 -> 13000 | J14: トップシールキャップ改 | L14: Z | M14: 40914 | Q14: 40926
B15: 4 | C15: 遠藤製作所 | D15: 遠藤製作所 | E15: SS4673 | F15: 1 | G15: 8600 | H15: =F15*G15 -> 8600 | J15: シールキャップ | L15: Z | M15: 40914 | Q15: 40926
B16: 5 | C16: 遠藤製作所 | D16: 遠藤製作所 | E16: SS4674 | F16: 1 | G16: 1500 | H16: =F16*G16 -> 1500 | J16: パッド | L16: Z | M16: 40914 | Q16: 40926
B17: 11 | C17: 遠藤製作所 | D17: 遠藤製作所 | E17: SS4675 | F17: 1 | G17: 2000 | H17: =F17*G17 -> 2000 | J17: シールナット | L17: Z | M17: 40914 | Q17: 40926
B18: 14 | C18: 遠藤製作所 | D18: 遠藤製作所 | E18: SS4716 | F18: 1 | G18: 10500 | H18: =F18*G18 -> 10500 | J18: ドロップインアダプタ（特X） | L18: Z | M18: 40914 | Q18: 40926
B19: 15 | C19: 遠藤製作所 | D19: 遠藤製作所 | E19: SS4717 | F19: 1 | G19: 3000 | H19: =F19*G19 -> 3000 | J19: アダプタナット | L19: Z | M19: 40914 | Q19: 40926
B20: 34 | C20: ミスミ | D20: ミスミ | E20: SHAN10 | F20: 1 | G20: 1760 | H20: =F20*G20 -> 1760 | J20: シャフトホルダ | L20: Y | M20: 40914 | P20: 40919 | Q20: 40919
B21: 34 | C21: ミスミ | D21: ミスミ | E21: SLSBF10-28-M6-N4-LKC | F21: 2 | G21: 1150 | H21: =F21*G21 -> 2300 | J21: 六角支柱 | L21: Y | M21: 40914 | P21: 40919 | Q21: 40919
B22: 34 | C22: ミスミ | D22: ミスミ | E22: SLSBG8-24-M4-N4-LKC | F22: 2 | G22: 1210 | H22: =F22*G22 -> 2420 | J22: 六角支柱 | L22: Y | M22: 40914 | P22: 40919 | Q22: 40919
B23: 35 | C23: ミスミ | D23: ミスミ | E23: LRLB5-10 | F23: 1 | G23: 570 | H23: =F23*G23 -> 570 | J23: 長尺ローレット付ボルト | L23: Y | M23: 40914 | P23: 40919 | Q23: 40919
B24: 35 | C24: ミスミ | D24: ミスミ | E24: SUTPB23 | F24: 1 | G24: 150 | H24: =F24*G24 -> 150 | J24: ブッシング | L24: Z | M24: 40914 | P24: 40919 | Q24: 40919
B25: 10 | C25: ミスミ | D25: ミスミ | E25: NPB11 | F25: 1 | G25: 72 | H25: =F25*G25 -> 72 | J25: Oリング | L25: Z | M25: 40914 | P25: 40919 | Q25: 40919
B26: 12 | C26: ミスミ | D26: ミスミ | E26: NPB5 | F26: 1 | G26: 66 | H26: =F26*G26 -> 66 | J26: Oリング | L26: Z | M26: 40914 | P26: 40919 | Q26: 40919
B27: 9 | C27: NOK | D27: ミスミ | E27: CO0517A | F27: 1 | G27: 16 | H27: =F27*G27 -> 16 | J27: Oリング（NOK） | L27: Z | M27: 40914 | P27: 40919 | Q27: 40919
B28: 35 | C28: 日本ピスコ | D28: ミスミ | E28: UB0640-20-B-L10 | F28: 1 | G28: 1000 | H28: =F28*G28 -> 1000 | J28: エアチューブ | L28: Z | M28: 40914 | P28: 40919 | Q28: 40919
B29: 33 | C29: ミスミ | D29: ミスミ | E29: BHDJ-PT-B-37-2 | F29: 1 | G29: 4854 | H29: =F29*G29 -> 4854 | J29: D-subコネクタハーネス | L29: Z | M29: 40914 | P29: 40919 | Q29: 40919
B30: 33 | C30: ミスミ | D30: ミスミ | E30: BHDJ-PT-B-9-2 | F30: 1 | G30: 2037 | H30: =F30*G30 -> 2037 | J30: D-subコネクタハーネス | L30: Z | M30: 40914 | P30: 40919 | Q30: 40919
B31: 33 | C31: ミスミ | D31: ミスミ | E31: ESAW-TCM310-5P | F31: 1 | G31: 3022 | H31: =F31*G31 -> 3022 | J31: コモンブロック端子台 | L31: Z | M31: 40914 | P31: 40919 | Q31: 40919
... B37: 19 | C37: SMC | D37: 都機工 | E37: KQ2U06-00 | F37: 10 | G37: 310 | H37: =F37*G37 -> 3100 | J37: 継手（SMC） | L37: Z | M37: 40914 | P37: 40919 | Q37: 40919
B38: 16 | C38: 機材 | D38: 機材 | E38: DIA-G | F38: 1 | H38: =F38*G38 -> 0 | J38: ガスケット（機材） | L38: Z | M38: 在庫使用
B39: 18 | C39: SMC | D39: 都機工 | E39: KQ2H06-02S | F39: 2 | G39: 154 | H39: =F39*G39 -> 308 | J39: 継手（SMC） | L39: Z | M39: 40914 | P39: 40919 | Q39: 40919
B40: 19 | C40: SMC | D40: 都機工 | E40: KCH06-02S | F40: 10 | G40: 450 | H40: =F40*G40 -> 4500 | J40: 継手（SMC） | L40: Z | M40: 40914 | P40: 40919 | Q40: 40919
B41: 21 | C41: 機材 | D41: 機材 | E41: 580092P | F41: 1 | H41: =F41*G41 -> 0 | J41: キャップシールパッキン | L41: Z | M41: 在庫使用
B42: 22 | C42: 機材 | D42: 機材 | E42: 580091V | F42: 1 | H42: =F42*G42 -> 0 | J42: 300CV用外容器・キャップセット | L42: Z | M42: 在庫使用
B43: 23 | C43: SET | D43: SET | E43: SV35HF | F43: 1 | H43: =F43*G43 -> 0 | J43: ピストンバルブ
B44: 24 | C44: SET | D44: SET | E44: SDP300 | F44: 1 | H44: =F44*G44 -> 0 | J44: ディスペンサ
B45: 25 | C45: 機材 | D45: 機材 | E45: 30-10MC4N-C | F45: 1 | H45: =F45*G45 -> 0 | J45: テフロン継手 | M45: 在庫使用
B46: 26 | C46: 機材 | D46: 機材 | E46: 30-10ME4N-C | F46: 1 | H46: =F46*G46 -> 0 | J46: テフロン継手 | M46: 在庫使用
B47: 27 | C47: 機材 | D47: 機材 | E47: PFA10-8 | F47: 1 | H47: =F47*G47 -> 0 | J47: テフロンホース（1ｍ） | M47: 在庫使用
...

Sheet 【94732】舟越製作所 原価一覧1-31出荷
B2: お客先名 | E2: 舟越製作所 | G2: 合計金額 | J2: =SUM(H:H) -> 572984
B3: 担当営業 | E3: 勝田
B4: 受注番号 | E4: 94732
B5: 希望納期 | E5: 40931
B6: 最終納品 | E6: 40939
B8: 見積り分類 | C8: メーカー | D8: 仕入先 | E8: 品名 / 型式 | F8: 数量 | G8: 単価 | H8: 金額 | I8: 分類合計 | J8: 詳細 | K8: 備考 | L8: 技術分類 | M8: 発注日 | N8: 発注 | O8: 納期 | P8: 入荷予定日 | Q8: 入荷日
B9: 1 | C9: 蛇の目 | D9: 蛇の目 | E9: JR2204N | F9: 1 | G9: 465000 | H9: =F9*G9 -> 465000 | M9: 40925 | P9: 40931 | Q9: 40931
B10: 1 | C10: 蛇の目 | D10: 蛇の目 | E10: 荷造り運賃 | F10: 1 | G10: 10000 | H10: =F10*G10 -> 10000 | M10: 40925
H11: =F11*G11 -> 0
H12: =F12*G12 -> 0
B13: 3 | C13: Asymtek | D13: Asymtek | E13: ZDA-1452010 | F13: 1 | H13: =F13*G13 -> 0 | J13: e-starディスペンスヘッド（10cc）
B14: 4 | C14: Asymtek | D14: Asymtek | E14: ZDA-2710370 | F14: 1 | H14: =F14*G14 -> 0 | J14: ACJ-3 CONTROLLER POWER UP（0.1Ω仕様）
B15: 5 | C15: 三ツ矢 | D15: 三ツ矢 | E15: MT-2702-P67 | F15: 1 | G15: 6800 | H15: =F15*G15 -> 6800 | J15: PJノズル27G L-2 | M15: 40925 | P15: 40932 | Q15: 40933
B16: 7 | C16: SET | D16: SET | E16: SDP300 | F16: 1 | H16: =F16*G16 -> 0 | J16: ディスペンサ
B17: 8 | C17: SET | D17: SET | E17: 1000BSH50-6 | F17: 1 | H17: =F17*G17 -> 0 | J17: 10cc シリンジアダプタ 1.8ｍ
B18: 9 | C18: EFD | D18: EFD | E18: 7018417 | F18: 1 | H18: =F18*G18 -> 0 | J18: 5127RTT-B
B19: 10 | C19: SET | D19: SET | E19: SH11LL-B | F19: 1 | H19: =F19*G19 -> 0 | J19: 10cc シリンジ
B20: 11 | C20: 機材 | D20: 機材 | E20: 880001B | F20: 1 | H20: =F20*G20 -> 0 | J20: チューブアダプター | M20: 在庫使用
H21: =F21*G21 -> 0
H22: =F22*G22 -> 0
B23: 6 | C23: ミスミ | D23: ミスミ | E23: SETGR10-25 | F23: 1 | G23: 380 | H23: =F23*G23 -> 380 | J23: 円形支柱 | K23: 発注No：94732（T-SAITO） | L23: Y | M23: 40921 | N23: 済 | P23: 40928 | Q23: 40928
B24: 6 | C24: ミスミ | D24: ミスミ | E24: SCDB-AMW-A37-b30-T20-l20-P10-J10-G10-Z4-F16-W10-M4 | F24: 1 | G24: 3220 | H24: =F24*G24 -> 3220 | J24: シャフトホルダ | K24: 発注No：94732（T-SAITO） | L24: Y | M24: 40921 | N24: 済 | P24: 40928 | Q24: 40928
B25: 6 | C25: ミスミ | D25: ミスミ | E25: SLSBWF7-30-LKC | F25: 4 | G25: 1010 | H25: =F25*G25 -> 4040 | J25: 六角支柱 | K25: 発注No：94732（T-SAITO） | L25: Y | M25: 40921 | N25: 済 | P25: 40928 | Q25: 40928
B26: 6 | C26: ミスミ | D26: ミスミ | E26: XSG25-CR | F26: 1 | G26: 15500 | H26: =F26*G26 -> 15500 | J26: X軸ステージ（リニアボール） | K26: 発注No：94732（T-SAITO） | L26: Y | M26: 40921 | N26: 済 | P26: 40928 | Q26: 40928
B27: 6 | C27: ミスミ | D27: ミスミ | E27: SCB2-5 | F27: 15 | G27: 80 | H27: =F27*G27 -> 1200 | J27: 六角穴付ボルト | K27: 発注No：94732（T-SAITO） | L27: Y | M27: 40921 | N27: 済 | P27: 40928 | Q27: 40928
B28: 6 | C28: ミスミ | D28: ミスミ | E28: CRKB4-10 | F28: 1 | G28: 78 | H28: =F28*G28 -> 78 | J28: 樹脂ローレット | K28: 発注No：94732（T-SAITO） | L28: Y | M28: 40921 | N28: 済 | P28: 40928 | Q28: 40928
B29: 12 | C29: ミスミ | D29: ミスミ | E29: @ECHN-20061106-00010 | F29: 1 | G29: 2814 | H29: =F29*G29 -> 2814 | J29: 特注ハーネス | M29: 技術在庫
B30: 12 | C30: ミスミ | D30: ミスミ | E30: @ECHN-20100219-00022 | F30: 1 | G30: 1933 | H30: =F30*G30 -> 1933 | J30: 特注ハーネス | M30: 技術在庫
B31: 6 | C31: アズワン | D31: 都機工 | E31: No.5 | F31: 1 | G31: 910 | H31: =F31*G31 -> 910 | J31: ミニカップ | M31: 40925 | P31: 40931 | Q31: 40931
B32: 13 | C32: SMC | D32: 都機工 | E32: IR1000-01BG | F32: 1 | G32: 6613 | H32: =F32*G32 -> 6613 | J32: 精密レギュレータ | M32: 40925 | P32: 40931 | Q32: 40931
B33: 13 | C33: SMC | D33: 都機工 | E33: KQ2L04-01S | F33: 2 | G33: 198 | H33: =F33*G33 -> 396 | J33: 継手 | M33: 40925 | P33: 40931 | Q33: 40931
H34: =F34*G34 -> 0
B35: 6 | C35: 遠藤製作所 | D35: 遠藤製作所 | E35: 94732-Y01 | F35: 1 | G35: 3200 | H35: =F35*G35 -> 3200 | J35: ツール取付板 | L35: Y | M35: 40925 | Q35: 40933
B36: 6 | C36: 遠藤製作所 | D36: 遠藤製作所 | E36: 94732-Y02 | F36: 1 | G36: 4800 | H36: =F36*G36 -> 4800 | J36: 25ステージ変換板金 | L36: Y | M36: 40925 | Q36: 40933
B37: 6 | C37: 遠藤製作所 | D37: 遠藤製作所 | E37: 94732-Y03 | F37: 1 | G37: 22200 | H37: =F37*G37 -> 22200 | J37: シリンジホルダ5cc-55cc（POMアダプタ付） | L37: Y | M37: 40925 | Q37: 40933
B38: 6 | C38: 遠藤製作所 | D38: 遠藤製作所 | E38: 94732-Y04 | F38: 1 | G38: 4800 | H38: =F38*G38 -> 4800 | J38: ノズルガイド（5127RTT） | L38: Y | M38: 40925 | Q38: 40933
B39: 6 | C39: 遠藤製作所 | D39: 遠藤製作所 | E39: 94732-Y05 | F39: 1 | G39: 3200 | H39: =F39*G39 -> 3200 | J39: e-star取付変換板 | L39: Y | M39: 40925 | Q39: 40933
B40: 6 | C40: 遠藤製作所 | D40: 遠藤製作所 | E40: 94732-Y06 | F40: 1 | G40: 4200 | H40: =F40*G40 -> 4200 | J40: e-star取付板（ショート） | L40: Y | M40: 40925 | Q40: 40933
B41: 6 | C41: 遠藤製作所 | D41: 遠藤製作所 | E41: 94732-Z01 | F41: 1 | G41: 5800 | H41: =F41*G41 -> 5800 | J41: 捨て打ちカップホルダ | L41: Z | M41: 40925 | Q41: 40933
B42: 6 | C42: 遠藤製作所 | D42: 遠藤製作所 | E42: 94732-Z02 | F42: 1 | G42: 5900 | H42: =F42*G42 -> 5900 | J42: カップ高さ調整板 | L42: Z | M42: 40925 | Q42: 40933
...

Sheet 【94756】 東亜電気工業（シャープ多気）1-24出荷
B2: お客先名 | E2: 東亜電気 | G2: 合計金額 | J2: =SUM(H:H) -> 1881941
B3: 担当営業 | E3: 真保
B4: 受注番号 | E4: 94756 | G4: 備考 | J4: 本件はタイショーで組立後、客先へ直送しますので、 手配品は入荷次第全てタイショーへ発送願います。
B5: 希望納期 | E5: 40931
B6: 最終納品
B8: 見積り分類 | C8: メーカー | D8: 仕入先 | E8: 品名 / 型式 | F8: 数量 | G8: 単価 | H8: 金額 | I8: 分類合計 | J8: 詳細 | K8: 備考 | L8: 技術分類 | M8: 発注日 | N8: 発注 | O8: 納期 | P8: 入荷予定日 | Q8: 入荷日
B9: 1 | C9: 蛇の目 | D9: 蛇の目 | E9: JR2203N | F9: 3 | G9: 302875 | H9: =F9*G9 -> 908625 | J9: ロボット取付板（P=130mm） | K9: 上野部長手配予定 | L9: - | M9: 在庫使用
B10: 2 | C10: タイショー | D10: タイショー | E10: - | F10: 0 | G10: 0 | H10: =F10*G10 -> 0 | J10: I/Oケーブル | K10: 項目14 SSSTに含まれています。 | L10: Z | O10: 40931
B11: 3 | C11: SET | D11: SET | E11: SDP400-30 | F11: 6 | G11: 18596 | H11: =F11*G11 -> 111576 | L11: -
B12: 4 | C12: タイショー | D12: タイショー | E12: SSST-001-2 | F12: 3 | G12: 4000 | H12: =F12*G12 -> 12000 | J12: ロボット取付板（P=130mm） | L12: Y | M12: 40903 | O12: 40931
B13: 4 | C13: タイショー | D13: タイショー | E13: SSST-002 | F13: 3 | G13: 2800 | H13: =F13*G13 -> 8400 | J13: スペーサーブロック | L13: Y | M13: 40903 | O13: 40931
B14: 4 | C14: タイショー | D14: タイショー | E14: SSST-003 | F14: 3 | G14: 1700 | H14: =F14*G14 -> 5100 | J14: L板金 | L14: Y | M14: 40903 | O14: 40931
B15: 4 | C15: タイショー | D15: タイショー | E15: SSST-004 | F15: 3 | G15: 3100 | H15: =F15*G15 -> 9300 | J15: Y軸変換板 | L15: Y | M15: 40903 | O15: 40931
B16: 4 | C16: タイショー | D16: タイショー | E16: SSST-005-21 | F16: 6 | G16: 3500 | H16: =F16*G16 -> 21000 | J16: シリンジホルダ（10cc） | L16: Y | M16: 40903 | O16: 40931
B17: 4 | C17: タイショー | D17: タイショー | E17: SSST-005-22 | F17: 6 | G17: 3300 | H17: =F17*G17 -> 19800 | J17: シリンジガイド（10cc） | L17: Y | M17: 40903 | O17: 40931
B18: 4 | C18: タイショー | D18: タイショー | E18: SSST-007-2 | F18: 6 | G18: 3700 | H18: =F18*G18 -> 22200 | J18: ノズルガイド（TEC-20N) | L18: Y | M18: 40903 | O18: 40931
B19: 4 | C19: タイショー | D19: タイショー | E19: SSST-008-1 | F19: 3 | G19: 4300 | H19: =F19*G19 -> 12900 | J19: 真空発生ユニット取付板 | L19: Y | M19: 40903 | O19: 40931
B20: 5 | C20: ミスミ | D20: ミスミ | E20: - | F20: 0 | G20: 0 | H20: =F20*G20 -> 0 | J20: 精密ノズルスペーサー | K20: 不要 | L20: - | M20: -
B21: 6 | C21: SMC | D21: 都機工 | E21: SYJ3140-5MZ-M5 | F21: 3 | G21: 5350 | H21: =F21*G21 -> 16050 | J21: 電磁弁 | L21: Z | M21: 40903 | P21: 40921 | Q21: 40919 | R21: 1/13ﾀｲｼｮｰ発送(送No.139598791290）
B22: 7 | C22: SMC | D22: 都機工 | E22: AW10-M5BG | F22: 3 | G22: 3430 | H22: =F22*G22 -> 10290 | J22: レギュレーター | L22: Z | M22: 40903 | P22: 40905 | Q22: 40905
B23: 7 | C23: SMC | D23: 都機工 | E23: MGJ6-5 | F23: 12 | G23: 6000 | H23: =F23*G23 -> 72000 | J23: シリンダ | L23: Z | M23: 40903 | P23: 40905 | Q23: 40905
B24: 7 | C24: SMC | D24: 都機工 | E24: AS1001F-04 | F24: 6 | G24: 770 | H24: =F24*G24 -> 4620 | J24: スピコン | L24: Z | M24: 40903 | P24: 40905 | Q24: 40905
B25: 8 | C25: SET | D25: SET | E25: 1000BSH50-6 | F25: 6 | G25: 495 | H25: =F25*G25 -> 2970 | L25: -
B26: 9 | C26: SET | D26: SET | E26: SH11CP-B | F26: 1 | G26: 705 | H26: =F26*G26 -> 705 | L26: -
B27: 10 | C27: SET | D27: SET | E27: 1000BSH52-6 | F27: 1 | G27: 613 | H27: =F27*G27 -> 613 | L27: -
B28: 11 | C28: SET | D28: SET | E28: SH12CP-B | F28: 1 | G28: 551 | H28: =F28*G28 -> 551 | L28: -
B29: 12 | C29: SET | D29: SET | E29: 7014838 | F29: 1 | G29: 400 | H29: =F29*G29 -> 400 | L29: -
B30: 13 | C30: SET | D30: SET | E30: SPN-20 | F30: 8 | G30: 3500 | H30: =F30*G30 -> 28000 | L30: -
B31: 14 | C31: タイショー | D31: タイショー | E31: SSST | F31: 3 | G31: 35000 | H31: =F31*G31 -> 105000 | J31: 組立設計工数 | L31: Z | M31: 40903 | O31: 40931
B32: 15 | C32: - | D32: - | E32: 特別値引き | H32: =F32*G32 -> 0 | L32: -
B33: 16 | C33: タイショー | D33: タイショー | E33: SSST-0017-2 | F33: 3 | G33: 5600 | H33: =F33*G33 -> 16800 | J33: ワークベース | L33: X | M33: 40903 | O33: 40931
B34: 16 | C34: タイショー | D34: タイショー | E34: SSST-0021-8 | F34: 3 | G34: 19100 | H34: =F34*G34 -> 57300 | J34: ワーク冶具 | L34: X | M34: 40903 | O34: 40931
B35: 16 | C35: タイショー | D35: タイショー | E35: SSST-0022-4 | F35: 12 | G35: 1700 | H35: =F35*G35 -> 20400 | J35: ワーク押さえプレート | L35: X | M35: 40903 | O35: 40931
B36: 16 | C36: タイショー | D36: タイショー | E36: SSST-0025-3(1) | F36: 3 | G36: 2100 | H36: =F36*G36 -> 6300 | J36: サイド板金 | L36: X | M36: 40903 | O36: 40931
B37: 16 | C37: タイショー | D37: タイショー | E37: SSST-0025-3(2) | F37: 3 | G37: 2100 | H37: =F37*G37 -> 6300 | J37: サイド板金 | M37: 40903 | O37: 40931
B38: 16 | C38: タイショー | D38: タイショー | E38: SSST-0028-1 | F38: 12 | G38: 2100 | H38: =F38*G38 -> 25200 | J38: 角押さえアダプター | L38: X | M38: 40903 | O38: 40931
B39: 16 | C39: タイショー | D39: タイショー | E39: SSST-0029-3 | F39: 3 | G39: 8400 | H39: =F39*G39 -> 25200 | J39: リニアガイドプレート | L39: X | M39: 40903 | O39: 40931
B40: 16 | C40: タイショー | D40: タイショー | E40: SSST-0030-6 | F40: 6 | G40: 800 | H40: =F40*G40 -> 4800 | J40: ワーク押さえプレート | L40: X | M40: 40903 | O40: 40931
B41: 16 | C41: タイショー | D41: タイショー | E41: SSST-0030-7 | F41: 24 | G41: 2400 | H41: =F41*G41 -> 57600 | J41: ワーク押さえプレート | K41: 仕様検討中につき、後日発注 | L41: X | M41: 40904 | O41: 40931
B42: 16 | C42: タイショー | D42: タイショー | E42: SSST-0031-1 | F42: 3 | G42: 9600 | H42: =F42*G42 -> 28800 | J42: エアシリンダ冶具（スライド部） | L42: X | M42: 40903 | O42: 40931
...

Sheet 【94763】 東亜電気工業（シャープ多気）1-24出荷
B2: お客先名 | E2: 東亜電気 | G2: 合計金額 | J2: =SUM(H:H) -> 1856785
B3: 担当営業 | E3: 真保
B4: 受注番号 | E4: 94763 | G4: 備考 | J4: 本件はタイショーで組立後、客先へ直送しますので、 手配品は入荷次第全てタイショーへ発送願います。
B5: 希望納期 | E5: 40931
B6: 最終納品
B8: 見積り分類 | C8: メーカー | D8: 仕入先 | E8: 品名 / 型式 | F8: 数量 | G8: 単価 | H8: 金額 | I8: 分類合計 | J8: 詳細 | K8: 備考 | L8: 技術分類 | M8: 発注日 | N8: 発注 | O8: 納期 | P8: 入荷予定日 | Q8: 入荷日
B9: 1 | C9: 蛇の目 | D9: 蛇の目 | E9: JR2203N | F9: 3 | G9: 302875 | H9: =F9*G9 -> 908625 | J9: ロボット取付板（P=130mm） | K9: 上野部長手配予定 | L9: - | M9: 在庫使用
B10: 2 | C10: タイショー | D10: タイショー | E10: - | F10: 0 | G10: 0 | H10: =F10*G10 -> 0 | J10: I/Oケーブル | K10: 項目14 SSSTに含まれています。 | L10: Z | O10: 40931
B11: 3 | C11: SET | D11: SET | E11: SDP400-30 | F11: 6 | G11: 18596 | H11: =F11*G11 -> 111576 | L11: -
B12: 4 | C12: タイショー | D12: タイショー | E12: SSST-001-2 | F12: 3 | G12: 4000 | H12: =F12*G12 -> 12000 | J12: ロボット取付板（P=130mm） | L12: Y | M12: 40903 | O12: 40931
B13: 4 | C13: タイショー | D13: タイショー | E13: SSST-002 | F13: 3 | G13: 2800 | H13: =F13*G13 -> 8400 | J13: スペーサーブロック | L13: Y | M13: 40903 | O13: 40931
B14: 4 | C14: タイショー | D14: タイショー | E14: SSST-003 | F14: 3 | G14: 1700 | H14: =F14*G14 -> 5100 | J14: L板金 | L14: Y | M14: 40903 | O14: 40931
B15: 4 | C15: タイショー | D15: タイショー | E15: SSST-004 | F15: 3 | G15: 3100 | H15: =F15*G15 -> 9300 | J15: Y軸変換板 | L15: Y | M15: 40903 | O15: 40931
B16: 4 | C16: タイショー | D16: タイショー | E16: SSST-005-21 | F16: 6 | G16: 3500 | H16: =F16*G16 -> 21000 | J16: シリンジホルダ（10cc） | L16: Y | M16: 40903 | O16: 40931
B17: 4 | C17: タイショー | D17: タイショー | E17: SSST-005-22 | F17: 6 | G17: 3300 | H17: =F17*G17 -> 19800 | J17: シリンジガイド（10cc） | L17: Y | M17: 40903 | O17: 40931
B18: 4 | C18: タイショー | D18: タイショー | E18: SSST-007-2 | F18: 6 | G18: 3700 | H18: =F18*G18 -> 22200 | J18: ノズルガイド（TEC-20N) | L18: Y | M18: 40903 | O18: 40931
B19: 4 | C19: タイショー | D19: タイショー | E19: SSST-008-1 | F19: 3 | G19: 4300 | H19: =F19*G19 -> 12900 | J19: 真空発生ユニット取付板 | L19: Y | M19: 40903 | O19: 40931
B20: 5 | C20: ミスミ | D20: ミスミ | E20: - | F20: 0 | G20: 0 | H20: =F20*G20 -> 0 | J20: 精密ノズルスペーサー | K20: 不要 | L20: - | N20: - | O20: - | P20: -
B21: 6 | C21: SMC | D21: 都機工 | E21: SYJ3140-5MZ-M5 | F21: 3 | G21: 5350 | H21: =F21*G21 -> 16050 | J21: 電磁弁 | L21: Z | M21: 40903 | P21: 40921 | Q21: 40919 | R21: 1/13ﾀｲｼｮｰ発送(送No.139598791290)
B22: 7 | C22: SMC | D22: 都機工 | E22: AW10-M5BG | F22: 3 | G22: 3430 | H22: =F22*G22 -> 10290 | J22: レギュレーター | L22: Z | M22: 40903 | P22: 40905 | Q22: 40905
B23: 7 | C23: SMC | D23: 都機工 | E23: MGJ6-5 | F23: 12 | G23: 6000 | H23: =F23*G23 -> 72000 | J23: シリンダ | L23: Z | M23: 40903 | P23: 40905 | Q23: 40905
B24: 7 | C24: SMC | D24: 都機工 | E24: AS1001F-04 | F24: 6 | G24: 770 | H24: =F24*G24 -> 4620 | J24: スピコン | L24: Z | M24: 40903 | P24: 40905 | Q24: 40905
B25: 8 | C25: SET | D25: SET | E25: 1000BSH50-6 | F25: 6 | G25: 495 | H25: =F25*G25 -> 2970 | L25: -
B26: 9 | C26: SET | D26: SET | E26: SH11CP-B | F26: 1 | G26: 705 | H26: =F26*G26 -> 705 | L26: -
B27: 10 | C27: SET | D27: SET | E27: SPN-20 | F27: 8 | G27: 551 | H27: =F27*G27 -> 4408 | L27: -
B28: 11 | C28: タイショー | D28: タイショー | E28: SSST | F28: 3 | G28: 35000 | H28: =F28*G28 -> 105000 | J28: 組立設計工数 | L28: - | M28: 40903 | O28: 40931
B29: 12 | C29: - | D29: - | E29: 特別値引き | H29: =F29*G29 -> 0 | L29: -
B30: 13 | C30: タイショー | D30: タイショー | E30: SSST-0017-2 | F30: 3 | G30: 5600 | H30: =F30*G30 -> 16800 | J30: ワークベース | L30: X | M30: 40903 | O30: 40931
B31: 13 | C31: タイショー | D31: タイショー | E31: SSST-0021-8 | F31: 3 | G31: 19100 | H31: =F31*G31 -> 57300 | J31: ワーク冶具 | L31: X | M31: 40903 | O31: 40931
B32: 13 | C32: タイショー | D32: タイショー | E32: SSST-0022-4 | F32: 12 | G32: 1700 | H32: =F32*G32 -> 20400 | J32: ワーク押さえプレート | L32: X | M32: 40903 | O32: 40931
B33: 13 | C33: タイショー | D33: タイショー | E33: SSST-0025-3(1) | F33: 3 | G33: 2100 | H33: =F33*G33 -> 6300 | J33: サイド板金 | L33: X | M33: 40903 | O33: 40931
B34: 13 | C34: タイショー | D34: タイショー | E34: SSST-0025-3(2) | F34: 3 | G34: 2100 | H34: =F34*G34 -> 6300 | J34: サイド板金 | M34: 40903
B35: 13 | C35: タイショー | D35: タイショー | E35: SSST-0028-1 | F35: 12 | G35: 2100 | H35: =F35*G35 -> 25200 | J35: 角押さえアダプター | L35: X | M35: 40903 | O35: 40931
B36: 13 | C36: タイショー | D36: タイショー | E36: SSST-0029-3 | F36: 3 | G36: 8400 | H36: =F36*G36 -> 25200 | J36: リニアガイドプレート | L36: X | M36: 40903 | O36: 40931
B37: 13 | C37: タイショー | D37: タイショー | E37: SSST-0030-6 | F37: 6 | G37: 800 | H37: =F37*G37 -> 4800 | J37: ワーク押さえプレート | L37: X | M37: 40903 | O37: 40931
B38: 13 | C38: タイショー | D38: タイショー | E38: SSST-0030-7 | F38: 24 | G38: 2400 | H38: =F38*G38 -> 57600 | J38: ワーク押さえプレート | K38: 仕様検討中につき、後日発注 | L38: X | M38: 40904 | O38: 40931
B39: 13 | C39: タイショー | D39: タイショー | E39: SSST-0031-1 | F39: 3 | G39: 9600 | H39: =F39*G39 -> 28800 | J39: エアシリンダ冶具（スライド部） | L39: X | M39: 40903 | O39: 40931
B40: 13 | C40: タイショー | D40: タイショー | E40: SSST-0033-1 | F40: 3 | G40: 1200 | H40: =F40*G40 -> 3600 | J40: フロント保護板金 | L40: X | M40: 40903 | O40: 40931
B41: 13 | C41: タイショー | D41: タイショー | E41: φ2.1 | F41: 12 | G41: 180 | H41: =F41*G41 -> 2160 | J41: ワッシャ追加工 | L41: X | M41: 40903 | O41: 40931
B42: 13 | C42: タイショー | D42: タイショー | E42: M2.5*12 | F42: 24 | G42: 35 | H42: =F42*G42 -> 840 | J42: 六角穴付ボルト | L42: X | M42: 40903 | O42: 40931
...

Sheet 【94857】 クレハ 原価一覧1-24出荷
B2: お客先名 | E2: ㈱クレハ（ニップン） | G2: 合計金額 | J2: =SUM(H:H) -> 68760
B3: 担当営業 | E3: 桑原
B4: 受注番号 | E4: 94857
B5: 希望納期 | E5: 40928
B6: 最終納品 | E6: 40932
B8: 見積り分類 | C8: メーカー | D8: 仕入先 | E8: 品名 / 型式 | F8: 数量 | G8: 単価 | H8: 金額 | I8: 分類合計 | J8: 詳細 | K8: 備考 | L8: 技術分類 | M8: 発注日 | N8: 発注 | O8: 納期 | P8: 入荷予定日 | Q8: 入荷日
B9: 1 | C9: Asymtek | D9: Asymtek | E9: ZDA-1420005 | F9: 2 | H9: =F9*G9 -> 0 | J9: E.STAR SHORT 5cc
B10: 2 | C10: Asymtek | D10: Asymtek | E10: ZDS-1400056 | F10: 2 | H10: =F10*G10 -> 0 | J10: ディスペンスエンジンＨタイプ
B11: 3 | C11: Asymtek | D11: Asymtek | E11: ZDS-1400014 | F11: -2 | H11: =F11*G11 -> 0 | J11: ディスペンスエンジン
B12: 4 | C12: EFD | D12: EFD | E12: 7017798 | F12: -2 | H12: =F12*G12 -> 0 | J12: 5110LL-B 5ccシリンジ
B13: 5 | C13: SET | D13: SET | E13: SH10LL-B | F13: 2 | H13: =F13*G13 -> 0 | J13: 5ccシリンジ
B14: 6 | C14: ミスミ | D14: ミスミ | E14: UJDST4-B | F14: 2 | G14: 220 | H14: =F14*G14 -> 440 | J14: ワンタッチ継手 | K14: 手配済み。 | L14: Z | M14: 40924 | N14: ○ | O14: 40925 | Q14: 40925
B15: 6 | C15: ミスミ | D15: ミスミ | E15: MJCNL6-1-B | F15: 4 | G15: 150 | H15: =F15*G15 -> 600 | J15: ワンタッチ継手 | K15: 手配済み。 | L15: Z | M15: 40924 | N15: ○ | O15: 40925 | Q15: 40925
B16: 6 | C16: ミスミ | D16: ミスミ | E16: SBD-S4-20 | F16: 4 | G16: 320 | H16: =F16*G16 -> 1280 | J16: ダンツキロッカク・ロッカク・パイプスペーサ | K16: 手配済み。 | L16: Z | M16: 40924 | N16: ○ | O16: 40925 | Q16: 40925
B17: 6 | C17: ミスミ | D17: ミスミ | E17: BVHBV6-6 | F17: 2 | G17: 1560 | H17: =F17*G17 -> 3120 | J17: チェンジバルブ | K17: 手配済み。 | L17: Z | M17: 40924 | N17: ○ | O17: 40925 | Q17: 40925
B18: 6 | C18: SMC | D18: 都機工 | E18: AC20A-01E | F18: 2 | G18: 7040 | H18: =F18*G18 -> 14080 | J18: レギュレータ | K18: 都機工 鈴木手配依頼済。注文書発行願います。 | L18: Z | M18: 40924 | N18: ○ | O18: 40928 | P18: 40928 | Q18: 40928
B19: 6 | C19: SMC | D19: 都機工 | E19: Y200T | F19: 2 | G19: 480 | H19: =F19*G19 -> 960 | J19: フィルター | K19: 都機工 鈴木手配依頼済。注文書発行願います。 | L19: Z | M19: 40924 | N19: ○ | O19: 40928 | P19: 40928 | Q19: 40928
B20: 6 | C20: SMC | D20: 都機工 | E20: IR1000-01G-X120 | F20: 2 | G20: 13440 | H20: 26880 | J20: 精密レギュレータ | K20: 都機工 鈴木手配依頼済。注文書発行願います。 | L20: Z | M20: 40924 | N20: ○ | O20: 40928 | P20: 40928 | Q20: 40928
B21: 6 | C21: 遠藤製作所 | D21: 遠藤製作所 | E21: 94857-Z01 | F21: 2 | G21: 3900 | H21: =F21*G21 -> 7800 | J21: ACJ-3 レギュレータ取付板 | K21: SKNP-0001より図番変更。先行依頼済み。 | L21: Z | M21: 40924 | N21: ○ | O21: 40928 | Q21: 40926
B22: 7 | E22: 送料 / 50 | F22: 2 | H22: =F22*G22 -> 0
B23: 8 | C23: Asymtek | D23: Asymtek | E23: ZDA-2710370 | F23: 2 | H23: =F23*G23 -> 0 | J23: ACJ-3 CONTROLLER POWER UP
B24: 9 | C24: 三ツ矢 | D24: 三ツ矢 | E24: MT3003-P67 | F24: 2 | G24: 6800 | H24: =F24*G24 -> 13600 | J24: PJ-Eノズル30G L=3mm | M24: 40924 | P24: 40932 | Q24: 40933
B25: 10 | C25: Asymtek | D25: Asymtek | E25: ZDP-1400200 | F25: 2 | H25: =F25*G25 -> 0 | J25: フルイドボディ
B26: 11 | C26: Asymtek | D26: Asymtek | E26: ZNP-0230060 | F26: 2 | H26: =F26*G26 -> 0 | J26: Ｏリング パープロ IDS6
B27: 12 | C27: Asymtek | D27: Asymtek | E27: ZDP-1400222 | F27: 2 | H27: =F27*G27 -> 0 | J27: シールホルダー
B28: 13 | E28: 995-952 | F28: 2 | H28: =F28*G28 -> 0 | J28: オムニシール 3-7
B29: 14 | E29: ZDP-0100102 | F29: 2 | H29: =F29*G29 -> 0 | J29: プレート
B30: 15 | C30: Asymtek | D30: Asymtek | E30: ZNP-0191215 | F30: 2 | H30: =F30*G30 -> 0 | J30: スプリング
B31: 16 | C31: Asymtek | D31: Asymtek | E31: ZNP-0230100 | F31: 2 | H31: =F31*G31 -> 0 | J31: Ｏリング パープロ IDS10
B32: 17 | C32: Asymtek | D32: Asymtek | E32: ZNP-5390004 | F32: 2 | H32: =F32*G32 -> 0 | J32: ニードルアダプター
B33: 18 | C33: EFD | D33: EFD | E33: 7020903 | F33: 2 | H33: =F33*G33 -> 0 | J33: 72523BP FIT:BARREL to 1/8NPTM ELB BPP
B34: 19 | C34: EFD | D34: EFD | E34: 5ccシリンジアダプター 1.8m / 1000BSH49-6 | F34: 2 | H34: =F34*G34 -> 0 | J34: 5ccシリンジアダプター 1.8m
H35: =F35*G35 -> 0
H37: =F37*G37 -> 0
H38: =F38*G38 -> 0
H39: =F39*G39 -> 0
H40: =F40*G40 -> 0
H41: =F41*G41 -> 0
H42: =F42*G42 -> 0
H43: =F43*G43 -> 0

Sheet 【94974】 アサヒ電子 原価一覧1-25出荷
B2: お客先名 | E2: アサヒ電子 | G2: 合計金額 | J2: =SUM(H:H) -> 732731
B3: 担当営業 | E3: 青木
B4: 受注番号 | E4: 94974
B5: 希望納期 | E5: 40920
B6: 最終納品
B8: 見積り分類 | C8: メーカー | D8: 仕入先 | E8: 品名 / 型式 | F8: 数量 | G8: 単価 | H8: 金額 | I8: 分類合計 | J8: 詳細 | K8: 備考 | L8: 技術分類 | M8: 発注日 | N8: 発注 | O8: 納期 | P8: 入荷予定日 | Q8: 入荷日
B9: 1 | C9: 蛇の目 | D9: 蛇の目 | E9: JR2303N-H | F9: 1 | G9: 546000 | H9: =F9*G9 -> 546000 | J9: ﾄｰﾙﾀｲﾌﾟ内部ｽｲｯﾁ仕様 | K9: 仙台（営）青木依頼分 | M9: 40914 | P9: 40926 | Q9: 40926
B10: 1 | C10: 蛇の目 | D10: 蛇の目 | E10: JR2303N-H追加費用 | F10: 1 | G10: 35000 | H10: =F10*G10 -> 35000 | M10: 40914 | P10: 40926 | Q10: 40926
B11: 1 | C11: 蛇の目 | D11: 蛇の目 | E11: IO-1増設ｹｰﾌﾞﾙ | F11: 1 | G11: 8400 | H11: =F11*G11 -> 8400 | M11: 40914 | P11: 40926 | Q11: 40926
B12: 1 | C12: 蛇の目 | D12: 蛇の目 | E12: 荷造り運賃 | F12: 1 | G12: 10000 | M12: 40914 | P12: 40926 | Q12: 40926
B13: 3 | C13: 蛇の目 | D13: 蛇の目 | E13: JR-TB | H13: =F13*G13 -> 0 | J13: ティーチングペンダント | M13: 在庫使用
B14: 5 | H14: =F14*G14 -> 0
B15: 5 | H15: =F15*G15 -> 0
B16: 6 | C16: 遠藤製作所 | D16: 遠藤製作所 | E16: ﾌﾞﾗｹｯﾄﾍﾞｰｽ/ 94974-X001 | F16: 1 | G16: 9500 | H16: =F16*G16 -> 9500 | M16: 40914 | Q16: 40920
B17: 6 | C17: 遠藤製作所 | D17: 遠藤製作所 | E17: ﾊﾞﾙﾌﾞ受けﾌﾞﾗｹﾄ/ 94974-X002 | F17: 1 | G17: 4500 | H17: =F17*G17 -> 4500 | M17: 40914 | Q17: 40920
B18: 6 | C18: 遠藤製作所 | D18: 遠藤製作所 | E18: ﾊﾞﾙﾌﾞ受け Ａ側/ 94974-X003 | F18: 1 | G18: 10500 | H18: =F18*G18 -> 10500 | M18: 40914 | Q18: 40920
B19: 6 | C19: 遠藤製作所 | D19: 遠藤製作所 | E19: ﾊﾞﾙﾌﾞ受け B側/ 94974-X004 | F19: 1 | G19: 12000 | H19: =F19*G19 -> 12000 | M19: 40914 | Q19: 40920
B20: 7 | H20: =F20*G20 -> 0
B21: 4 | C21: タカチ電機 | D21: 都機工 | E21: FCWS400-150-100KGSS加工組立 | F21: 1 | G21: 26550 | H21: =F21*G21 -> 26550 | J21: フリーサイズケース | K21: 見積書No.499264 | L21: Z | M21: 40914 | P21: 40932 | Q21: 40932
B22: 4 | C22: タカチ電機 | D22: 都機工 | E22: FCSC400-150-1加工組立 | F22: 1 | G22: 7990 | H22: =F22*G22 -> 7990 | J22: フリーサイズケース | K22: 見積書No.499264 | L22: Z | M22: 40914 | P22: 40932 | Q22: 40932
B23: 4 | C23: ミスミ | D23: ミスミ | E23: MRB350 | F23: 1 | G23: 1080 | H23: =F23*G23 -> 1080 | J23: DINレール | L23: Z | M23: 40914 | P23: 40919 | Q23: 40919
B24: 4 | C24: ミスミ | D24: ミスミ | E24: MWS-DS37A-HT37 | F24: 1 | G24: 3350 | H24: =F24*G24 -> 3350 | J24: D-Subコネクタ端子台 | L24: Z | M24: 40914 | P24: 40919 | Q24: 40919
B25: 4 | C25: ミスミ | D25: ミスミ | E25: MWS-DS25A-HT25 | F25: 1 | G25: 2490 | H25: =F25*G25 -> 2490 | J25: D-Subコネクタ端子台 | L25: Z | M25: 40914 | P25: 40919 | Q25: 40919
B26: 4 | C26: ミスミ | D26: ミスミ | E26: ESAW-TCM310-5P | F26: 1 | G26: 3022 | H26: =F26*G26 -> 3022 | J26: コモンブロック端子台 | L26: Z | M26: 40914 | P26: 40919 | Q26: 40919
B27: 4 | C27: ミスミ | D27: ミスミ | E27: NEDJ-PS-SB-37-1.5 | F27: 1 | G27: 5719 | H27: =F27*G27 -> 5719 | J27: D-Subコネクタハーネス | L27: Z | M27: 40914 | P27: 40919 | Q27: 40919
B28: 4 | C28: ミスミ | D28: ミスミ | E28: NEDJ-SS-SB-25-1.5 | F28: 1 | G28: 4293 | H28: =F28*G28 -> 4293 | J28: D-Subコネクタハーネス | L28: Z | M28: 40914 | P28: 40919 | Q28: 40919
B29: 4 | C29: ミスミ | D29: ミスミ | E29: F1.25-M3 | F29: 1 | G29: 460 | H29: =F29*G29 -> 460 | J29: 圧着端子（Y型） | L29: Z | M29: 40914 | P29: 40919 | Q29: 40919
B30: 4 | C30: ミスミ | D30: ミスミ | E30: AXSH212-VC-1PD2-2EB-1.5-1AC-2DA-F | F30: 1 | G30: 6615 | H30: =F30*G30 -> 6615 | J30: 外部ｽｲｯﾁBOX | L30: Z | M30: 40914 | P30: 40919 | Q30: 40919
B31: 6 | C31: 遠藤製作所 | D31: 遠藤製作所 | E31: ﾌﾞﾗｹｯﾄﾍﾞｰｽ/ 94974-X001-1 | F31: 1 | G31: 12000 | H31: =F31*G31 -> 12000 | M31: 40920 | Q31: 40926
B32: 6 | C32: 遠藤製作所 | D32: 遠藤製作所 | E32: ﾌﾞﾗｹﾄﾍﾞｰｽﾛﾝｸﾞ/ 94974-X005 | F32: 1 | G32: 15000 | H32: =F32*G32 -> 15000 | M32: 40920 | Q32: 40926
B33: 6 | C33: 遠藤製作所 | D33: 遠藤製作所 | E33: ﾊﾞﾙﾌﾞ受け Ａ側/ 94974-X006 | F33: 1 | G33: 4200 | H33: =F33*G33 -> 4200 | M33: 40920 | Q33: 40926
B34: 6 | C34: 遠藤製作所 | D34: 遠藤製作所 | E34: ﾊﾞﾙﾌﾞ受け B側/ 94974-X007 | F34: 1 | G34: 5200 | H34: =F34*G34 -> 5200 | M34: 40920 | Q34: 40926
B35: 6 | C35: ミスミ | D35: ミスミ | E35: MS3-15 | F35: 76 | G35: 19 | H35: =F35*G35 -> 1444 | J35: ノックﾋﾟﾝ | M35: 40920 | P35: 40921 | Q35: 40921
B36: 6 | C36: ミスミ | D36: ミスミ | E36: MS3-20 | F36: 24 | G36: 39 | H36: =F36*G36 -> 936 | J36: ノックﾋﾟﾝ | M36: 40920 | P36: 40921 | Q36: 40921
B37: 4 | C37: ミスミ | D37: ミスミ | E37: UL1007-24-BE-305 | F37: 1 | G37: 2060 | H37: =F37*G37 -> 2060 | J37: 単芯電線 | M37: 40920 | P37: 40924 | Q37: 40925
B38: 4 | C38: ミスミ | D38: ミスミ | E38: VTUB3.2-W-10 | F38: 1 | G38: 622 | H38: =F38*G38 -> 622 | J38: ﾏｰｸﾁｭｰﾌﾞ | M38: 40920 | P38: 40921 | Q38: 40921
B39: 1 | C39: 蛇の目 | D39: 蛇の目 | E39: 品番：961053015 | F39: 2 | G39: 1400 | H39: =F39*G39 -> 2800 | J39: Ｚ軸強化ばね(6.3kgf）JR2303N用 | M39: 40921 | P39: 40927 | Q39: 40927
B40: 1 | C40: 蛇の目 | D40: 蛇の目 | E40: 品番：961053015 送料 | F40: 1 | G40: 1000 | H40: =F40*G40 -> 1000 | M40: 40921

Sheet 【95000】 コーセル 原価一覧1-31出荷
B2: お客先名 | E2: コーセル | G2: 合計金額 | J2: =SUM(H:H) -> 701001
B3: 担当営業 | E3: 桑原
B4: 受注番号 | E4: 95000
B5: 希望納期 | E5: 40927
B6: 最終納品
B8: 見積り分類 | C8: メーカー | D8: 仕入先 | E8: 品名 / 型式 | F8: 数量 | G8: 単価 | H8: 金額 | I8: 分類合計 | J8: 詳細 | K8: 備考 | L8: 技術分類 | M8: 発注日 | N8: 発注 | O8: 納期 | P8: 入荷予定日 | Q8: 入荷日
B9: 1 | C9: 蛇の目 | D9: 蛇の目 | E9: JR2403N | F9: 1 | G9: 607000 | H9: 607000 | J9: JR2403N | M9: 40914 | P9: 40931 | Q9: 40931
B10: 2 | C10: 蛇の目 | D10: 蛇の目 | E10: JR-TB | F10: 1 | J10: ティーチングペンダント | M10: 在庫使用
B11: 3 | C11: SET | D11: SET | E11: SV97MS | F11: 1 | J11: スプレーバルブMS
B12: 4 | C12: SET | D12: SET | E12: SVC600 | F12: 1 | J12: スプレーバルブコントローラ
B13: 6 | C13: 機材 | D13: 機材 | E13: 30-10ME4N-C | F13: 1 | J13: テフロン継手φ10 L型 | M13: 在庫使用
B14: 7 | C14: 機材 | D14: 機材 | E14: 30-10MC4N-C | F14: 1 | J14: テフロン継手φ10 ストレート型 | M14: 在庫使用
B15: 8 | C15: 機材 | D15: 機材 | E15: 7014868 | F15: 1 | J15: 2197A異型継手 | M15: 在庫使用
B16: 12 | C16: SET | D16: SET | E16: SH22-0.25-B | F16: 1 | J16: 22G GPニードル
B17: 13 | C17: 機材 | D17: 機材 | E17: PFA10-8 | F17: 1 | J17: φ10テフロンホース | M17: 在庫使用
B18: 9 | C18: 遠藤製作所 | D18: 遠藤製作所 | E18: 95000-Y01 | F18: 1 | G18: 5900 | H18: =F18*G18 -> 5900 | J18: ツール板 | L18: Y | M18: 40914 | Q18: 40926
B19: 9 | C19: 遠藤製作所 | D19: 遠藤製作所 | E19: SS40079 | F19: 1 | G19: 13800 | H19: =F19*G19 -> 13800 | J19: 740,725,780用ホルダ（P=25） | L19: Y | M19: 40914 | Q19: 40926
B20: 11 | C20: 遠藤製作所 | D20: 遠藤製作所 | E20: 95000-Z01 | F20: 1 | G20: 7500 | H20: =F20*G20 -> 7500 | J20: ノズル洗浄カップ | L20: Z | M20: 40914 | Q20: 40926
B21: 11 | C21: 遠藤製作所 | D21: 遠藤製作所 | E21: 95000-Z02 | F21: 1 | G21: 5900 | H21: =F21*G21 -> 5900 | J21: カップ固定板金 | L21: Z | M21: 40914 | Q21: 40926
B22: 11 | C22: 遠藤製作所 | D22: 遠藤製作所 | E22: 95000-Z03 | F22: 1 | G22: 4800 | H22: =F22*G22 -> 4800 | J22: カップ固定ブロック | L22: Z | M22: 40914 | Q22: 40926
B23: 11 | C23: 遠藤製作所 | D23: 遠藤製作所 | E23: 95000-Z04 | F23: 1 | G23: 9000 | H23: =F23*G23 -> 9000 | J23: 端子台取付板 | L23: Z | M23: 40914 | Q23: 40931
B24: 5 | C24: SMC | D24: 都機工 | E24: CDM2L32-250-C73C | F24: 1 | G24: 9460 | H24: =F24*G24 -> 9460 | J24: シリンダー | M24: 40914 | P24: 40924 | Q24: 1/16(1/17大阪発送) | R24: 入荷後大阪（営）桑原さんに送付
B25: 5 | C25: SMC | D25: 都機工 | E25: AS2201F-01-06 | F25: 2 | G25: 880 | H25: =F25*G25 -> 1760 | J25: スピコン | M25: 40914 | P25: 40919 | Q25: 1/11(1/17大阪発送) | R25: 入荷後大阪（営）桑原さんに送付
B26: 5 | C26: SMC | D26: 都機工 | E26: AN103-01 | F26: 2 | G26: 270 | H26: =F26*G26 -> 540 | J26: サイレンサー | M26: 40914 | P26: 40919 | Q26: 1/11(1/17大阪発送) | R26: 入荷後大阪（営）桑原さんに送付
B27: 5 | C27: SMC | D27: 都機工 | E27: VZM450-01-34R | F27: 1 | G27: 7290 | H27: =F27*G27 -> 7290 | J27: 5ポートメカニカルバルブ | M27: 40914 | P27: 40919 | Q27: 1/11(1/17大阪発送) | R27: 入荷後大阪（営）桑原さんに送付
B28: 5 | C28: SMC | D28: 都機工 | E28: KQ2L06-01 | F28: 10 | G28: 192 | H28: =F28*G28 -> 1920 | J28: 継手 | M28: 40914 | P28: 40919 | Q28: 1/11(1/17大阪発送) | R28: 入荷後大阪（営）桑原さんに送付
B29: 11 | C29: SMC | D29: 都機工 | E29: AW20-01BE-R | F29: 1 | G29: 4340 | H29: =F29*G29 -> 4340 | J29: フィルターレギュレータ | L29: Z | M29: 40914 | P29: 40919 | Q29: 40919
B30: 11 | C30: SMC | D30: 都機工 | E30: SYJ514-5MZ-01 | F30: 1 | G30: 4420 | H30: =F30*G30 -> 4420 | J30: 電磁弁 | L30: Z | M30: 40914 | P30: 40919 | Q30: 40919
B31: 11 | C31: アズワン | D31: 都機工 | E31: No.60 | F31: 1 | G31: 2180 | H31: =F31*G31 -> 2180 | J31: ミニカップ | M31: 40914 | P31: 40921 | Q31: 40921
B32: 11 | C32: ミスミ | D32: ミスミ | E32: MRB300 | F32: 1 | G32: 930 | H32: =F32*G32 -> 930 | J32: DINレール | L32: Z | M32: 40914 | P32: 40919 | Q32: 40919
B33: 11 | C33: ミスミ | D33: ミスミ | E33: MWS-DS37A-HT37 | F33: 1 | G33: 3350 | H33: =F33*G33 -> 3350 | J33: D-Subコネクタ端子台 | L33: Z | M33: 40914 | P33: 40919 | Q33: 40919
B34: 11 | C34: ミスミ | D34: ミスミ | E34: ESAW-TCM310-5P | F34: 1 | G34: 3022 | H34: =F34*G34 -> 3022 | J34: コモンブロック端子台 | L34: Z | M34: 40914 | P34: 40919 | Q34: 40919
B35: 11 | C35: ミスミ | D35: ミスミ | E35: NEDJ-PS-SB-37-2 | F35: 1 | G35: 5869 | H35: =F35*G35 -> 5869 | J35: D-Subコネクタハーネス | L35: Z | M35: 40914 | P35: 40919 | Q35: 40919
B36: 11 | C36: ミスミ | D36: ミスミ | E36: NEDJ-P-SB-9-2 | F36: 1 | G36: 1560 | H36: =F36*G36 -> 1560 | J36: D-Subコネクタハーネス | L36: Z | M36: 40914 | P36: 40919 | Q36: 40919
B37: 11 | C37: ミスミ | D37: ミスミ | E37: F1.25-M3 | F37: 1 | G37: 460 | H37: =F37*G37 -> 460 | J37: 圧着端子（Y型） | L37: Z | M37: 40914 | P37: 40919 | Q37: 40919
H38: =F38*G38 -> 0
H39: =F39*G39 -> 0
H40: =F40*G40 -> 0
H41: =F41*G41 -> 0
H42: =F42*G42 -> 0
...

Sheet 【95034】 東亜電気工業（シャープ多気）1-5出荷
B2: お客先名 | E2: 東亜電気工業 | G2: 合計金額 | J2: =SUM(H:H) -> 303389
B3: 担当営業 | E3: 真保
B4: 受注番号 | E4: 95034 | G4: 備考 | J4: 琶麗出荷品
B5: 希望納期 | E5: -
B6: 最終納品
B8: 見積り分類 | C8: メーカー | D8: 仕入先 | E8: 品名 / 型式 | F8: 数量 | G8: 単価 | H8: 金額 | I8: 分類合計 | J8: 詳細 | K8: 備考 | L8: 技術分類 | M8: 発注日 | N8: 発注 | O8: 納期 | P8: 入荷予定日 | Q8: 入荷日
B9: 1 | C9: 蛇の目 | D9: 蛇の目 | E9: JRV2203 | F9: 11 | H9: =F9*G9 -> 0 | L9: - | M9: 在庫使用
B10: 2 | C10: - | D10: - | E10: I/Oケーブル | F10: 11 | G10: 0 | H10: =F10*G10 -> 0 | J10: I/Oケーブル | L10: -
B11: 3 | C11: 蛇の目 | D11: 蛇の目 | E11: JRV-TB | F11: 2 | H11: =F11*G11 -> 0 | J11: JRV-TB | L11: - | M11: 在庫使用
B12: 4 | C12: 蛇の目 | D12: 蛇の目 | E12: PC編集ソフト | F12: 1 | J12: PC編集ソフト | L12: - | M12: 在庫使用
B13: 5 | C13: ミスミ | D13: ミスミ | E13: PNUIC-REX-USB60F-R | F13: 1 | G13: 5200 | H13: 5200 | J13: PC通信ケーブル | L13: - | M13: 40904 | N13: ○ | P13: 40914 | Q13: 1/6(佐藤Ｍ渡済)
B14: 5 | C14: ミスミ | D14: ミスミ | E14: DGC-9SS | F14: 1 | G14: 203 | H14: 203 | J14: PC通信ケーブル | L14: - | M14: 40904 | N14: ○ | P14: 40914 | Q14: 1/6(佐藤Ｍ渡済)
B15: 6 | C15: SET | D15: SET | E15: SDP400-30 | F15: 22 | L15: -
B16: 7 | C16: SET | D16: SET | E16: 1000BSH50-6 | F16: 22 | L16: -
B17: 8 | C17: SET | D17: SET | E17: SH11CP-B | F17: 11 | L17: -
B18: 9 | C18: SET | D18: SET | E18: SPN-20 | F18: 22 | L18: -
B19: 10 | C19: - | D19: - | E19: 組立工賃 | F19: 11 | L19: -
B20: 11 | C20: - | D20: - | E20: 送料 | F20: 11 | L20: -
B21: その他 | C21: SMC | D21: 都機工 | E21: MGJ6-5 | F21: 44 | G21: 5460 | H21: 240240 | M21: 40903 | P21: 40914 | Q21: ..1/...5
B22: その他 | C22: ﾐｽﾐ | D22: ﾐｽﾐ | E22: CBSTSR3-5 | F22: 100 | G22: 150 | H22: 15000 | M22: 40903 | P22: 40905 | Q22: 40905
B23: その他 | C23: ﾐｽﾐ | D23: ﾐｽﾐ | E23: KNCLSS4-6-10 | F23: 90 | G23: 178 | H23: 16020 | M23: 40903 | P23: 40905 | Q23: 40905
B24: その他 | C24: ﾐｽﾐ | D24: ﾐｽﾐ | E24: SHCDG4-16 | F24: 50 | G24: 165 | H24: 8250 | M24: 40903 | P24: 40905 | Q24: 40905
B25: その他 | C25: ﾐｽﾐ | D25: ﾐｽﾐ | E25: DE-9PF-N | F25: 22 | G25: 350 | H25: 7700 | M25: 40904 | P25: 40914 | Q25: 1/6(佐藤Ｍ渡済)
B26: その他 | C26: ﾐｽﾐ | D26: ﾐｽﾐ | E26: DE-C8-J9-F41R | F26: 22 | G26: 448 | H26: 9856 | M26: 40904 | P26: 40914 | Q26: 1/6(佐藤Ｍ渡済)
B27: その他 | C27: 秋月電子 | D27: 秋月電子 | E27: D-SUBコネクタ（オス） | F27: 23 | G27: 40 | H27: =F27*G27 -> 920 | M27: 直接購入 | N27: - | O27: - | P27: - | Q27: -

Sheet 【95126】 東亜電気工業（シャープ多気）1-16出荷
B2: お客先名 | E2: 東亜電気工業 | G2: 合計金額 | J2: =SUM(H:H) -> 23436
B3: 担当営業 | E3: 真保
B4: 受注番号 | E4: 95126 | G4: 備考 | J4: 琶麗出荷品
B5: 希望納期 | E5: -
B6: 最終納品
B8: 見積り分類 | C8: メーカー | D8: 仕入先 | E8: 品名 / 型式 | F8: 数量 | G8: 単価 | H8: 金額 | I8: 分類合計 | J8: 詳細 | K8: 備考 | L8: 技術分類 | M8: 発注日 | N8: 発注 | O8: 納期 | P8: 入荷予定日 | Q8: 入荷日
B9: 1 | C9: 蛇の目 | D9: 蛇の目 | E9: JRV2203 | F9: 1 | L9: - | M9: 在庫使用
B10: 2 | C10: - | D10: - | E10: I/Oケーブル | F10: 1 | J10: I/Oケーブル | L10: -
B11: 3 | C11: SET | D11: SET | E11: SDP400-30 | F11: 2
B12: 4 | C12: SET | D12: SET | E12: 1000BSH50-6 | F12: 2
B13: 5 | C13: SET | D13: SET | E13: SH11CP-B | F13: 1
B14: 6 | C14: SET | D14: SET | E14: SPN-20 | F14: 2
B15: 7 | C15: - | D15: - | E15: 組立工賃 | F15: 1 | L15: -
B16: 8 | C16: - | D16: - | E16: 送料 | F16: 1 | L16: -
B17: その他 | C17: SMC | D17: 都機工 | E17: MGJ6-5 | F17: 4 | G17: 5460 | H17: =F17*G17 -> 21840 | M17: 40913 | P17: 40919 | Q17: 40919 | R17: 1/13ﾀｲｼｮｰ発送(送No.139598791290)
B18: その他 | C18: ミスミ | D18: ミスミ | E18: DE-9PF-N | F18: 2 | G18: 350 | H18: =F18*G18 -> 700 | M18: 40913 | P18: 40918 | Q18: 40918
B19: その他 | C19: ミスミ | D19: ミスミ | E19: DE-C8-J9-F41R | F19: 2 | G19: 448 | H19: =F19*G19 -> 896 | M19: 40913 | P19: 40918 | Q19: 40918

Sheet 【95200】 ケイマック 原価一覧1-30出荷
B2: お客先名 | E2: ケイ・マック | G2: 合計金額 | J2: =SUM(H:H) -> 228200
B3: 担当営業 | E3: 桑原
B4: 受注番号 | E4: 95200
B5: 希望納期 | E5: 40928
B6: 最終納品 | E6: 40934
B8: 見積り分類 | C8: メーカー | D8: 仕入先 | E8: 品名 / 型式 | F8: 数量 | G8: 単価 | H8: 金額 | I8: 分類合計 | J8: 詳細 | K8: 備考 | L8: 技術分類 | M8: 発注日 | N8: 発注 | O8: 納期 | P8: 入荷予定日 | Q8: 入荷日
B9: 3 | C9: 遠藤製作所 | D9: 遠藤製作所 | E9: 95200-Y01 | F9: 2 | G9: 7500 | H9: =F9*G9 -> 15000 | J9: ロボット取付板（リニアボール3D用） | L9: Y | M9: 40920 | P9: 40933
B10: 3 | C10: 遠藤製作所 | D10: 遠藤製作所 | E10: 94301-Y02 | F10: 2 | G10: 3800 | H10: =F10*G10 -> 7600 | J10: ステージ固定板（リニアボール3D用） | L10: Y | M10: 40920 | P10: 40933
B11: 3 | C11: 遠藤製作所 | D11: 遠藤製作所 | E11: 94301-Y03 | F11: 2 | G11: 2500 | H11: =F11*G11 -> 5000 | J11: シリンジ+バルブ取付上板（リニアボール3D用） | L11: Y | M11: 40920 | P11: 40933
B12: 3 | C12: 遠藤製作所 | D12: 遠藤製作所 | E12: 95200-Y04 | F12: 2 | G12: 2400 | H12: =F12*G12 -> 4800 | J12: シリンジ+バルブ取付下板（リニアボール3D用） | L12: Y | M12: 40920 | P12: 40933
B13: 3 | C13: 遠藤製作所 | D13: 遠藤製作所 | E13: SS40705 | F13: 2 | G13: 22200 | H13: =F13*G13 -> 44400 | J13: シリンジアダプタ5CC-55CC （POMアダプタ付） | L13: Y | M13: 40920 | P13: 40933
B14: 3 | C14: ミスミ | D14: ミスミ | E14: XYZSSG40-CU | F14: 2 | G14: 54000 | H14: =F14*G14 -> 108000 | J14: XYZステージ（リニアボール） | L14: Y | M14: 40919 | P14: 40926 | Q14: 40926
B15: 4,5 | C15: ミスミ | D15: ミスミ | E15: %WRFH-4050-120110-15 | F15: 2 | G15: 21700 | H15: =F15*G15 -> 43400 | J15: 特注ハーネス | L15: Z | M15: 40919 | P15: 40933 | Q15: 40933
B16: 1 | C16: 蛇の目 | D16: 蛇の目 | E16: JR2203-SET03 | F16: 2 | H16: =F16*G16 -> 0 | J16: 2203N | M16: 在庫使用
B17: 2 | C17: 蛇の目 | D17: 蛇の目 | E17: JR-TB | F17: 2 | H17: =F17*G17 -> 0 | J17: ティーチングボックス | M17: 在庫使用
B18: 6 | C18: SET | D18: SET | E18: SDP300 | F18: 2 | H18: =F18*G18 -> 0 | J18: ディスペンサ
B19: 7 | C19: SET | D19: SET | E19: SH13CP-B | F19: 2 | H19: =F19*G19 -> 0 | J19: 55ccシリンジ/ピストン
B20: 8 | C20: SET | D20: SET | E20: 1000BSH52 | F20: 2 | H20: =F20*G20 -> 0 | J20: 30/55ccシリンジアダプタ
B21: 9 | E21: 搬入調整費 | F21: 2 | H21: =F21*G21 -> 0
H22: =F22*G22 -> 0

Sheet 【95446】キヤノン電子 原価一覧1-31出荷
B2: お客先名 | E2: キヤノン電子 | G2: 合計金額 | J2: =SUM(H:H) -> 2355982
B3: 担当営業 | E3: 勝田
B4: 受注番号 | E4: 95446
B5: 希望納期 | E5: 40933
B6: 最終納品 | E6: 40938
B8: 見積り分類 | C8: メーカー | D8: 仕入先 | E8: 品名 / 型式 | F8: 数量 | G8: 単価 | H8: 金額 | I8: 分類合計 | J8: 詳細 | K8: 備考 | L8: 技術分類 | M8: 発注日 | N8: 発注 | O8: 納期 | P8: 入荷予定日 | Q8: 入荷日
B9: 1 | C9: 蛇の目 | D9: 蛇の目 | E9: JR2203NH | F9: 6 | G9: 305000 | H9: =F9*G9 -> 1830000 | M9: 40925 | P9: 40928 | Q9: 40928
B10: 1 | C10: 蛇の目 | D10: 蛇の目 | E10: 荷造り運賃 | F10: 6 | G10: 10000 | H10: =F10*G10 -> 60000 | M10: 40925
B11: 3 | C11: 蛇の目 | D11: 蛇の目 | E11: JR-TB | F11: 1 | H11: =F11*G11 -> 0 | K11: 在庫品 | M11: 在庫使用
H13: =F13*G13 -> 0
B14: 4 | C14: Asymtek | D14: Asymtek | E14: ZDA-1420010 | F14: 6 | H14: =F14*G14 -> 0 | J14: e-starディスペンスヘッド（10cc）
B15: 5 | C15: Asymtek | D15: Asymtek | E15: ZDS-1420021 | F15: -6 | H15: =F15*G15 -> 0 | J15: アキュバルブキット（ショート）
B16: 6 | C16: Asymtek | D16: Asymtek | E16: ZDS-1450201 | F16: 6 | H16: =F16*G16 -> 0 | J16: コニカルバルブ
B17: 7 | C17: Asymtek | D17: Asymtek | E17: ZDA-2710370 | F17: 6 | H17: =F17*G17 -> 0 | J17: ACJ-3 CONTROLLER POWER UP（0.1Ω仕様）
B18: 8 | C18: 三ツ矢 | D18: 三ツ矢 | E18: MT-2701-P67 | F18: 12 | G18: 5800 | H18: =F18*G18 -> 69600 | J18: PJノズル27G L-1 | M18: 40925 | P18: 40933 | Q18: 40933
B19: 9 | C19: アズワン | D19: 都機工 | E19: HS-50E-B | F19: 6 | G19: 19800 | H19: =F19*G19 -> 118800 | J19: シリンジ撹拌システム | K19: 型式変更 | M19: 40925
B20: 10 | C20: SMC | D20: 都機工 | E20: IR1000-01BG | F20: 6 | G20: 6613 | H20: =F20*G20 -> 39678 | J20: レギュレータ | M20: 40925 | P20: 40931 | Q20: 40933
B21: 13 | C21: ミスミ | D21: ミスミ | E21: HXCW12-8-2 | F21: 18 | G21: 490 | H21: =F21*G21 -> 8820 | J21: マグネットリングタイプ | M21: 40925 | P21: 40931 | Q21: 40931
B22: 14 | C22: SET | D22: SET | E22: SH11LL-B | F22: 3 | H22: =F22*G22 -> 0 | J22: 10ｃｃシリンジ
B23: 15 | E23: 7017976 | F23: 1 | H23: =F23*G23 -> 0 | J23: 5113-B
B24: 16 | C24: SMC | D24: 都機工 | E24: KQ2H04-01S | F24: 12 | G24: 128 | H24: =F24*G24 -> 1536 | J24: 継手 | M24: 40925 | P24: 40931 | Q24: 40933
H25: =F25*G25 -> 0
H26: =F26*G26 -> 0
B27: 10 | C27: ミスミ | D27: ミスミ | E27: SETGS12-60-SC10-M5-N5 | F27: 24 | G27: 910 | H27: =F27*G27 -> 21840 | J27: 円形支柱 | L27: Y | M27: 40925 | P27: 40931 | Q27: 40931
B28: 10 | C28: ミスミ | D28: ミスミ | E28: SLSBWF7-24 | F28: 24 | G28: 500 | H28: =F28*G28 -> 12000 | J28: 六角支柱 | L28: Y | M28: 40925 | P28: 40931 | Q28: 40931
B29: 10 | C29: ミスミ | D29: ミスミ | E29: @ECHN-20100219-00022 | F29: 6 | G29: 1933 | H29: =F29*G29 -> 11598 | J29: 特注ハーネス | K29: 購入依頼書にて、在庫品として発注済 | L29: Z | M29: 技術在庫 | N29: ○ | P29: 40935
B30: 10 | C30: アズワン | D30: 都機工 | E30: No.5 | F30: 1 | G30: 910 | H30: =F30*G30 -> 910 | J30: ミニカップ | L30: Z | M30: 40925 | P30: 40931 | Q30: 40933
H32: =F32*G32 -> 0
B33: 10 | C33: 遠藤製作所 | D33: 遠藤製作所 | E33: SS40635 | F33: 6 | G33: 6200 | H33: =F33*G33 -> 37200 | J33: ツール取付板 | L33: Y | M33: 40925 | Q33: 40934
B34: 10 | C34: 遠藤製作所 | D34: 遠藤製作所 | E34: SS3193 | F34: 6 | G34: 9800 | H34: =F34*G34 -> 58800 | J34: ベース板 | L34: X | M34: 40925 | Q34: 40934
B35: 10 | C35: 遠藤製作所 | D35: 遠藤製作所 | E35: SS3194 | F35: 6 | G35: 7200 | H35: =F35*G35 -> 43200 | J35: スターラ台 | L35: Z | M35: 40925 | Q35: 40934
B36: 10 | C36: 遠藤製作所 | D36: 遠藤製作所 | E36: SS40636 | F36: 6 | G36: 2800 | H36: =F36*G36 -> 16800 | J36: 捨て打ちベース板 | L36: Z | M36: 40925 | Q36: 40934
B37: 10 | C37: 遠藤製作所 | D37: 遠藤製作所 | E37: SS40637 | F37: 6 | G37: 4200 | H37: =F37*G37 -> 25200 | J37: カップ押え | L37: Z | M37: 40925 | Q37: 40934
H38: =F38*G38 -> 0
H39: =F39*G39 -> 0
H40: =F40*G40 -> 0
H41: =F41*G41 -> 0
H42: =F42*G42 -> 0
H43: =F43*G43 -> 0
H44: =F44*G44 -> 0

Sheet 【95600】  (有)仲田屋　原価一覧1-25出荷
B2: お客先名 | E2: (有)仲田屋 | G2: 合計金額 | J2: =SUM(H:H) -> 193000
B3: 担当営業 | E3: 青木
B4: 受注番号 | E4: 95600
B5: 希望納期 | E5: 40932
B6: 最終納品
B8: 見積り分類 | C8: メーカー | D8: 仕入先 | E8: 品名 / 型式 | F8: 数量 | G8: 単価 | H8: 金額 | I8: 分類合計 | J8: 詳細 | K8: 備考 | L8: 技術分類 | M8: 発注日 | N8: 発注 | O8: 納期 | P8: 入荷予定日 | Q8: 入荷日
B9: 1 | C9: SET | D9: SET | E9: SV３５ＨＦ | F9: 1 | H9: =F9*G9 -> 0 | J9: ﾊｲﾌﾛｰﾋﾟｽﾄﾝﾊﾞﾙﾌﾞ
B10: 2 | D10: ﾘｷｯﾄﾞｼｽﾃﾑ | E10: SVF-2035 | F10: 1 | G10: 112000 | H10: 112000 | J10: ｽﾃﾝﾚｽﾍﾞｯｾﾙ(内容器11.8リットル） | M10: 40920 | P10: 40935 | Q10: 40928
B11: 3 | D11: ﾘｷｯﾄﾞｼｽﾃﾑ | E11: ＡＲＧ－0.7Ｍ | F11: 1 | G11: 5950 | H11: 5950 | J11: ﾚｷﾞｭﾚｰﾀ-(高圧） | M11: 40920 | P11: 40935 | Q11: 40928
B12: 4 | D12: ﾘｷｯﾄﾞｼｽﾃﾑ | E12: SRV-0.6MS | F12: 1 | G12: 9600 | H12: 9600 | J12: SUSﾘﾘｰﾌ弁 | M12: 40920 | P12: 40935 | Q12: 40928
B13: 5 | D13: ﾘｷｯﾄﾞｼｽﾃﾑ | E13: 5 | F13: 1 | G13: 9300 | H13: 9300 | J13: φ１２ｻｸｼｮﾝﾊﾟｲﾌﾟ・継ぎ手 | M13: 40920 | P13: 40935 | Q13: 40928
B14: 6 | D14: ﾘｷｯﾄﾞｼｽﾃﾑ | E14: 5 | F14: 1 | G14: 28000 | H14: 28000 | J14: φ173.5ﾌｫﾛｰﾌﾟﾚｰﾄ | M14: 40920 | P14: 40935 | Q14: 40928
B15: 7 | C15: SET | D15: SET | E15: SDP300 | F15: 1 | H15: =+G15*F15 -> 0 | J15: ﾃﾞｨｽﾍﾟﾝｻ
B16: 8 | C16: 機材 | D16: 機材 | E16: PFA12-10 | F16: 1 | H16: =+G16*F16 -> 0 | J16: φ12mmﾃﾌﾛﾝﾎｰｽ 3m | M16: 在庫使用
B17: 9 | C17: 遠藤製作所 | D17: 遠藤製作所 | E17: SV35-HF用継ぎ手（ｾﾒﾀﾞｲﾝ） | F17: 2 | G17: 9000 | H17: 18000 | J17: ﾉｽﾞﾙｱﾀﾞﾌﾟﾀｰ（POM材使用） | M17: 40931 | Q17: 40931
B18: 10 | D18: 日本ｽｳｪ-ｼﾞﾛｯｸ | E18: SS-12M0-2-4 | F18: 1 | G18: 2630 | H18: 2630 | J18: おすｴﾙﾎﾞｰφ12×NPT1/4 ＃SS12-E | M18: 40931 | P18: 40932 | Q18: 40932
B19: 11 | E19: 1 | F19: 1 | H19: =+G19*F19 -> 0 | J19: 出精値引き
B20: 12 | E20: 1 | F20: 1 | H20: =+G20*F20 -> 0 | J20: 特別値引き
B30: 15 | E30: 調整費
B31: 16 | E31: 諸経費
B32: 17 | E32: 特別値引き
B33: 1 | C33: ﾘｷﾂﾄ | D33: ﾘｷｯﾄ | E33: 5 | F33: 1 | G33: 7000 | H33: 7000 | J33: φ17,.φ14ﾊｰﾌﾕﾆｵﾝ,pt3/8ｿｹｯﾄ | M33: 40928 | P33: 40928 | Q33: 40928
B34: 10 | C34: ﾐｽﾐ | D34: ﾐｽﾐ | E34: FWRBN-D30-V22-T4 | F34: 2 | G34: 260 | H34: 520 | J34: ゴムワッシャ | M34: 40931 | P34: 40938 | Q34: 40938

Sheet 【94615】 NDK 原価一覧
B2: お客先名 | E2: NDK | G2: 合計金額 | J2: =SUM(H:H) -> 7954380
B3: 担当営業 | E3: 青木
B4: 受注番号 | E4: 94615
B5: 希望納期 | E5: 40954
B6: 最終納品
B8: 見積り分類 | C8: メーカー | D8: 仕入先 | E8: 品名 / 型式 | F8: 数量 | G8: 単価 | H8: 金額 | I8: 分類合計 | J8: 詳細 | K8: 備考 | L8: 技術分類 | M8: 発注日 | N8: 発注 | O8: 納期 | P8: 入荷予定日 | Q8: 入荷日
B9: 1 | C9: Asymtek | D9: Asymtek | E9: ZDA-1420510 | F9: 3 | H9: =F9*G9 -> 0
B10: 2 | C10: Asymtek | D10: Asymtek | E10: ZDA-2710370 | F10: 3 | H10: =F10*G10 -> 0
B11: 3 | C11: Asymtek | D11: Asymtek | E11: ZDA-2410321 | F11: 3 | H11: =F11*G11 -> 0
B12: 4 | C12: Asymtek | D12: Asymtek | E12: MT-30005-P67 | F12: 3 | H12: =F12*G12 -> 0
B13: 5 | C13: 蛇の目 | D13: 蛇の目 | E13: JR2203NH | F13: 3 | G13: 360000 | H13: =F13*G13 -> 1080000 | K13: 14307 | M13: 40892 | N13: ○ | O13: ﾀﾞｲﾔ直送
B14: 5 | C14: 蛇の目 | D14: 蛇の目 | E14: 荷造り運賃 | F14: 3 | G14: 10000 | H14: =F14*G14 -> 30000 | K14: 14307 | M14: 40892 | N14: ○
B15: 6 | C15: 蛇の目 | D15: 蛇の目 | E15: COM増設 | F15: 3 | G15: 20000 | H15: =F15*G15 -> 60000 | K15: 14307 | M15: 40892 | N15: ○ | O15: ﾀﾞｲﾔ直送
B16: 7 | C16: 蛇の目 | D16: 蛇の目 | E16: JR-TB | F16: 3 | G16: 38000 | H16: =F16*G16 -> 114000 | M16: 在庫使用 | N16: ×
B17: 8 | C17: パナソニック | D17: 蛇の目 | E17: A110 | F17: 3 | G17: 155400 | H17: =F17*G17 -> 466200 | J17: ANMA110 | K17: 14308 | L17: Z | M17: 40892 | N17: ○ | O17: ﾀﾞｲﾔ直送
B18: 8 | C18: パナソニック | D18: 蛇の目 | E18: RS232C | F18: 3 | G18: 12000 | H18: =F18*G18 -> 36000 | J18: 960536106 | K18: 14308 | L18: Z | M18: 40892 | N18: ○ | O18: ﾀﾞｲﾔ直送
B19: 8 | C19: パナソニック | D19: 蛇の目 | E19: 送料 | F19: 3 | G19: 1000 | H19: =F19*G19 -> 3000 | J19: - | K19: 14308 | L19: Z | M19: 40892 | N19: ○
B20: 9 | C20: パナソニック | D20: 蛇の目 | E20: CSマウントカメラ | F20: 3 | G20: 54600 | H20: =F20*G20 -> 163800 | J20: ANM832 | K20: 14308 | L20: Z | M20: 40892 | N20: ○ | O20: ﾀﾞｲﾔ直送
B21: 10 | C21: パナソニック | D21: 蛇の目 | E21: 操作キーパット | F21: 3 | G21: 7900 | H21: =F21*G21 -> 23700 | J21: ANM85202 | K21: 14308 | L21: Z | M21: 40892 | N21: ○ | O21: ﾀﾞｲﾔ直送
B22: 11 | C22: パナソニック | D22: 松下制御テクノ | E22: レンズ | F22: 3 | G22: 23000 | H22: =F22*G22 -> 69000 | J22: ANB846NL | K22: 14305 | L22: Z | M22: 40892 | N22: ○ | P22: 40919 | Q22: 40919
B23: 12 | C23: オプトアート | D23: 都機工 | E23: リアコンバーターレンズ | F23: 3 | G23: 10800 | H23: =F23*G23 -> 32400 | J23: TVR02 | K23: 14306 | L23: Z | M23: 40892 | N23: ○ | O23: 40928 | P23: 2011/12/28(残１ヶ) | Q23: 12/26 2ヶ 12/28 1ヶ
B24: 12 | C24: オプトアート | D24: 都機工 | E24: 送料 | F24: 3 | G24: 1000 | H24: =F24*G24 -> 3000 | J24: - | K24: 14306 | L24: Z | M24: 40892 | N24: ○
B25: 12 | C25: VSテクノロジー | D25: VSテクノロジー | E25: 中間リング | F25: 6 | G25: 1380 | H25: =F25*G25 -> 8280 | J25: SV-EXR10 | K25: 14304 | L25: Z | M25: 40892 | N25: ○ | P25: 40897 | Q25: 40897
B26: 13 | C26: CCS | D26: CCS | E26: LED安定照明器 | F26: 3 | G26: 44000 | H26: =F26*G26 -> 132000 | J26: LDR2-32RD | K26: 14303 | L26: Z | M26: 40892 | N26: ○ | P26: 40928
B27: 13 | C27: CCS | D27: CCS | E27: コントローラー | F27: 3 | G27: 13600 | H27: =F27*G27 -> 40800 | J27: PSB-512VL | K27: 14303 | L27: Z | M27: 40892 | N27: ○ | P27: 40928
B28: 13 | C28: CCS | D28: CCS | E28: ケーブル | F28: 3 | G28: 2400 | H28: =F28*G28 -> 7200 | J28: CB-2 | K28: 14303 | L28: Z | M28: 40892 | N28: ○ | P28: 40928
B29: 14 | C29: オジックとダイア | D29: オジックとダイア | E29: 搬送及び制御機構 | F29: 3 | G29: 1895000 | H29: =F29*G29 -> 5685000 | J29: 搬送装置 | K29: 14264 | M29: 40892 | N29: ○ | P29: 2月中旬
B30: 15 | E30: 調整費 | F30: 3 | H30: =F30*G30 -> 0
B31: 16 | E31: 諸経費 | F31: 3 | H31: =F31*G31 -> 0
B32: 17 | E32: 特別値引き | F32: 3

Sheet 12.01.05 【95113】 スエヒロ通商 原価一覧2-7
B2: お客先名 | E2: スエヒロ通商㈱ | G2: 合計金額 | J2: =SUM(H:H) -> 35792
B3: 担当営業 | E3: 青木
B4: 受注番号 | E4: 95113
B5: 希望納期 | E5: 40927
B6: 最終納品
B8: 見積り分類 | C8: メーカー | D8: 仕入先 | E8: 品名 / 型式 | F8: 数量 | G8: 単価 | H8: 金額 | I8: 分類合計 | J8: 詳細 | K8: 備考 | L8: 技術分類 | M8: 発注日 | N8: 発注 | O8: 納期 | P8: 入荷予定日 | Q8: 入荷日
B9: 1 | C9: SET | D9: SET | E9: SV97MS | F9: 2 | J9: スプレーバルブMS
B10: 2 | C10: SET | D10: SET | E10: SS-6MO-2-2 | F10: 2 | J10: おすｴﾙﾎﾞｰ φ6×NPT 1/8 | P10: 40931
B11: 3 | C11: SET | D11: SET | E11: SVC600 | F11: 2 | J11: スプレーバルブコントローラ
B12: 4 | C12: 機材 | D12: 機材 | E12: 200F755 | F12: 2 | J12: ﾌｨﾙﾀｰ/REG 5MICRON | M12: 在庫使用
B13: 5 | C13: 機材 | D13: 機材 | E13: KQ2H06-02S | F13: 4 | J13: 継手ﾊｰﾌﾕﾆｵﾝ φ6× 1/4PT | M13: 在庫使用
B14: 6 | C14: 機材 | D14: 機材 | E14: PFA6-4 | F14: 1 | J14: φ6mmﾃﾌﾛﾝﾎｰｽ ※3ｍ×2本 (TOTAL 6m） | M14: 在庫使用
B15: 7 | C15: 機材 | D15: 機材 | E15: 5 | F15: 2 | J15: SV0830:SVF-0197-STA ﾀﾝｸ | M15: 在庫使用
B16: 8 | C16: SET | D16: SET | E16: SH30-B | F16: 2 | J16: 30G GPﾆｰﾄﾞﾙﾉｽﾞﾙ12.7mm(ﾗﾍﾞﾝﾀﾞｰ）50入り
B18: 9 | C18: 遠藤製作所 | D18: 遠藤製作所 | E18: 95113-X001 | F18: 1 | G18: 8900 | H18: =F18*G18 -> 8900 | J18: SV97用受けブラケット | L18: Y | M18: 40921 | Q18: 40933
B19: 9 | C19: 遠藤製作所 | D19: 遠藤製作所 | E19: 95113-X002 | F19: 2 | G19: 5800 | H19: =F19*G19 -> 11600 | J19: SV97ﾊﾞﾙﾌﾞ受け Ａ | L19: Y | M19: 40921 | Q19: 40926
B20: 9 | C20: 遠藤製作所 | D20: 遠藤製作所 | E20: 95113-X003 | F20: 2 | G20: 6200 | H20: =F20*G20 -> 12400 | J20: SV97ﾊﾞﾙﾌﾞ受け B | L20: Y | M20: 40921 | Q20: 40926
B21: 9 | C21: ミスミ | D21: ミスミ | E21: MS3-20 | F21: 6 | G21: 39 | H21: =F21*G21 -> 234 | J21: ﾉｯｸﾋﾟﾝφ3-20mm | L21: Y | M21: 40921 | P21: 40924 | Q21: 40924
B22: 9 | C22: ミスミ | D22: ミスミ | E22: MS3-15 | F22: 42 | G22: 39 | H22: =F22*G22 -> 1638 | J22: ﾉｯｸﾋﾟﾝφ3-15mm | L22: Y | M22: 40921 | P22: 40924 | Q22: 40924
B23: 9 | C23: ミスミ | D23: ミスミ | E23: SCB-4-40 | F23: 4 | G23: 95 | H23: =F23*G23 -> 380 | J23: 六角穴付ﾎﾞﾙﾄ(M4×40mm） | L23: Y | M23: 40921 | P23: 40924 | Q23: 40924
B24: 9 | C24: ミスミ | D24: ミスミ | E24: SCB-4-14 | F24: 8 | G24: 80 | H24: =F24*G24 -> 640 | J24: 六角穴付ﾎﾞﾙﾄ(M4×14mm） | L24: Y | M24: 40921 | P24: 40924 | Q24: 40924
H25: =F25*G25 -> 0
H26: =F26*G26 -> 0
H27: =F27*G27 -> 0
H28: =F28*G28 -> 0
H29: =F29*G29 -> 0
H30: =F30*G30 -> 0
H31: =F31*G31 -> 0
H32: =F32*G32 -> 0
H33: =F33*G33 -> 0
H34: =F34*G34 -> 0
H35: =F35*G35 -> 0
H36: =F36*G36 -> 0
... H44: =F44*G44 -> 0

Sheet 12.01.24 【95331】住友電装 原価一覧2-4出荷
B2: お客先名 | E2: 住友電装 | G2: 合計金額 | J2: =SUM(H:H) -> 74794
B3: 担当営業 | E3: 真保
B4: 受注番号 | E4: 95331
B5: 希望納期 | E5: 40939
B6: 最終納品 | E6: 40943
B8: 見積り分類 | C8: メーカー | D8: 仕入先 | E8: 品名 / 型式 | F8: 数量 | G8: 単価 | H8: 金額 | I8: 分類合計 | J8: 詳細 | K8: 備考 | L8: 技術分類 | M8: 発注日 | N8: 発注 | O8: 納期 | P8: 入荷予定日 | Q8: 入荷日
B9: 1 | C9: ミスミ | D9: ミスミ | E9: XYZEG40 | F9: 1 | G9: 33800 | H9: =F9*G9 -> 33800 | J9: 3軸ステージ | K9: 見積No：WOSM0039798A | L9: Y | M9: 40932 | P9: 40938 | Q9: 40938
B10: 1 | C10: ミスミ | D10: ミスミ | E10: SLSBWRK7-25 | F10: 2 | G10: 280 | H10: =F10*G10 -> 560 | J10: 六角支柱 | K10: 見積No：WOSM0039798A | L10: Y | M10: 40932 | P10: 40938 | Q10: 40938
B11: 1 | C11: ミスミ | D11: ミスミ | E11: SCB3-10 | F11: 20 | G11: 25 | H11: =F11*G11 -> 500 | J11: 六角穴付ボルト | K11: 見積No：WOSM0039798A | L11: Y | M11: 40932 | P11: 40938 | Q11: 40938
B12: 1 | C12: ミスミ | D12: ミスミ | E12: SCB3-15 | F12: 20 | G12: 25 | H12: =F12*G12 -> 500 | J12: 六角穴付ボルト | K12: 見積No：WOSM0039798A | L12: Y | M12: 40932 | P12: 40938 | Q12: 40938
B13: 1 | C13: ミスミ | D13: ミスミ | E13: SCB4-10 | F13: 20 | G13: 25 | H13: =F13*G13 -> 500 | J13: 六角穴付ボルト | K13: 見積No：WOSM0039798A | L13: Y | M13: 40932 | P13: 40938 | Q13: 40938
B14: 1 | C14: ミスミ | D14: ミスミ | E14: SCB4-15 | F14: 20 | G14: 30 | H14: =F14*G14 -> 600 | J14: 六角穴付ボルト | K14: 見積No：WOSM0039798A | L14: Y | M14: 40932 | P14: 40938 | Q14: 40938
B15: 1 | C15: ミスミ | D15: ミスミ | E15: SCB4-35 | F15: 2 | G15: 88 | H15: =F15*G15 -> 176 | J15: 六角穴付ボルト | K15: 見積No：WOSM0039798A | L15: Y | M15: 40932 | P15: 40938 | Q15: 40938
B16: 4 | C16: ミスミ | D16: ミスミ | E16: NEDJ-PT-SB-9-2 | F16: 1 | G16: 2098 | H16: =F16*G16 -> 2098 | J16: D-subコネクタハーネス | K16: 見積No：WOSM0039798A | L16: Z | M16: 40932 | P16: 40938 | Q16: 40938
B17: 4 | C17: ミスミ | D17: ミスミ | E17: F1.25-M3 | F17: 1 | G17: 460 | H17: =F17*G17 -> 460 | J17: 圧着端子（Y型） | K17: 見積No：WOSM0039798A | L17: Z | M17: 40932 | P17: 40938 | Q17: 40938
B18: 1 | C18: 遠藤製作所 | D18: 遠藤製作所 | E18: 95331-Y01 | F18: 1 | G18: 3400 | H18: =F18*G18 -> 3400 | J18: ツール板（3軸アリ） | L18: Y | M18: 40932 | Q18: 40939
B19: 1 | C19: 遠藤製作所 | D19: 遠藤製作所 | E19: 95331-Y02 | F19: 1 | G19: 3200 | H19: =F19*G19 -> 3200 | J19: 揺れ防止板 | L19: Y | M19: 40932 | Q19: 40939
B20: 1 | C20: 遠藤製作所 | D20: 遠藤製作所 | E20: 95331-Y03 | F20: 1 | G20: 3600 | H20: =F20*G20 -> 3600 | J20: 揺れ防止ステー板金 | L20: Y | M20: 40932 | Q20: 40939
B21: 1 | C21: 遠藤製作所 | D21: 遠藤製作所 | E21: 95331-Y04 | F21: 1 | G21: 1500 | H21: =F21*G21 -> 1500 | J21: 3軸アリ取付スペーサ | L21: Y | M21: 40932 | Q21: 40940
B22: 1 | C22: 遠藤製作所 | D22: 遠藤製作所 | E22: 95331-Y05 | F22: 1 | G22: 3200 | H22: =F22*G22 -> 3200 | J22: バルブ取付板金スペーサ | L22: Y | M22: 40932 | Q22: 40939
B23: 1 | C23: 遠藤製作所 | D23: 遠藤製作所 | E23: SS40079 | F23: 1 | G23: 13800 | H23: =F23*G23 -> 13800 | J23: 740,752,780用ホルダ（P=25） | L23: Y | M23: 40932 | Q23: 40939
B24: 1 | C24: 遠藤製作所 | D24: 遠藤製作所 | E24: SS40143 | F24: 1 | G24: 2400 | H24: =F24*G24 -> 2400 | J24: バルブ取付板 | L24: Y | M24: 40932 | Q24: 40939
B25: 1 | C25: 遠藤製作所 | D25: 遠藤製作所 | E25: SS40144 | F25: 1 | G25: 4500 | H25: =F25*G25 -> 4500 | J25: シリンジガイド | L25: Y | M25: 40932 | Q25: 40939

Sheet 12.01.24 【95354】協栄電気（新電元） 原価一覧
B2: お客先名 | E2: 協栄電気（新電元） | G2: 合計金額 | J2: =SUM(H:H) -> 40481
B3: 担当営業 | E3: 勝田
B4: 受注番号 | E4: 95354
B5: 希望納期 | E5: 40939
B6: 最終納品 | E6: 40942
B8: 見積り分類 | C8: メーカー | D8: 仕入先 | E8: 品名 / 型式 | F8: 数量 | G8: 単価 | H8: 金額 | I8: 分類合計 | J8: 詳細 | K8: 備考 | L8: 技術分類 | M8: 発注日 | N8: 発注 | O8: 納期 | P8: 入荷予定日 | Q8: 入荷日
B9: 8 | C9: ミスミ | D9: ミスミ | E9: C1-SCDB-12045740 | F9: 1 | G9: 3820 | H9: =F9*G9 -> 3820 | J9: シャフトホルダ | K9: 受注No：WOSC00E94247 | L9: Y | M9: 40932 | N9: 済 | P9: 40939 | Q9: 40939
B10: 8 | C10: ミスミ | D10: ミスミ | E10: NEDU-PS-SB-9-3.0 | F10: 1 | G10: 2935 | H10: =F10*G10 -> 2935 | J10: Dsubハーネス | K10: 受注No：WOSC00E94247 | L10: Y | M10: 40932 | N10: 済 | P10: 40939 | Q10: 40939
B11: 8 | C11: ミスミ | D11: ミスミ | E11: HD-LN-4-40-05 | F11: 1 | G11: 226 | H11: =F11*G11 -> 226 | J11: Dsubロック金具 | K11: 受注No：WOSC00E94247 | L11: Y | M11: 40932 | N11: 済 | P11: 40939 | Q11: 40939
H12: =F12*G12 -> 0
H13: =F13*G13 -> 0
B14: 7 | C14: 遠藤製作所 | D14: 遠藤製作所 | E14: 95354-Y01 | F14: 1 | G14: 19000 | H14: =F14*G14 -> 19000 | J14: ツール板 | L14: Y | M14: 40933 | Q14: 40939
B15: 7 | C15: 遠藤製作所 | D15: 遠藤製作所 | E15: 95354-Y02 | F15: 1 | G15: 14500 | H15: =F15*G15 -> 14500 | J15: SV91バルブホルダ（ピン付） | L15: Y | M15: 40933 | Q15: 40941

Sheet 12.01.27 【95875】 白河オリンパス 原価一覧
B2: お客先名 | E2: ㈱ｲｲﾀﾞ様(白河ｵﾘﾝﾊﾟｽ) | G2: 合計金額 | J2: =SUM(H:H) -> 12000
B3: 担当営業 | E3: 青木
B4: 受注番号 | E4: 95875
B5: 希望納期 | E5: 40935
B6: 最終納品
B8: 見積り分類 | C8: メーカー | D8: 仕入先 | E8: 品名 / 型式 | F8: 数量 | G8: 単価 | H8: 金額 | I8: 分類合計 | J8: 詳細 | K8: 備考 | L8: 技術分類 | M8: 発注日 | N8: 発注 | O8: 納期 | P8: 入荷予定日 | Q8: 入荷日
B9: 1 | C9: 遠藤製作所 | D9: 遠藤製作所 | E9: ﾆｰﾄﾞﾙｶﾞｲﾄﾞﾛﾝｸﾞ 95875-Y001 | F9: 1 | G9: 12000 | H9: =F9*G9 -> 12000 | I9: Ｙ | J9: ﾉｽﾞﾙｶﾞｲﾄﾞ10mm延長 | K9: 遠藤製作所図面渡し済み | M9: 40947 | Q9: 40954

Sheet 12.01.31 【95480】大津屋（旭電器工業） 原価一覧
B2: お客先名 | E2: 大津屋（旭電器工業） | G2: 合計金額 | J2: =SUM(H:H) -> 99831
B3: 担当営業 | E3: 真保
B4: 受注番号 | E4: 95480
B5: 希望納期 | E5: 40947
B6: 最終納品
